Workbook

Sheet About
A1: BTaDLP BAU Transmission and Distribution Loss Percentage | B1: West Virginia | C1: 46184 | I1: Alabama | J1: AL
B2: =LOOKUP(B1,I1:J50,J1:J50) -> WV | I2: Alaska | J2: AK
A3: Source: | B3: Imports and Export EIA SEDS | I3: Arizona | J3: AZ
B4: Energy Information Administration | I4: Arkansas | J4: AR
B5: 2024 | I5: California | J5: CA
B6: Example Link: https://www.eia.gov/electricity/state/virginia/state_tables.php | I6: Colorado | J6: CO
B7: Tab 10: Imports and Exports (lines 15,28) | I7: Connecticut | J7: CT
I8: Delaware | J8: DE
A9: Notes: | I9: Florida | J9: FL
A10: This variable represents the percentage difference in generation | I10: Georgia | J10: GA
A11: and delivered energy from the U.S. power system. | I11: Hawaii | J11: HI
I12: Idaho | J12: ID
I13: Illinois | J13: IL
I14: Indiana | J14: IN
I15: Iowa | J15: IA
I16: Kansas | J16: KS
I17: Kentucky | J17: KY
I18: Louisiana | J18: LA
I19: Maine | J19: ME
I20: Maryland | J20: MD
I21: Massachusetts | J21: MA
I22: Michigan | J22: MI
I23: Minnesota | J23: MN
... I50: Wyoming | J50: WY

Sheet calc
E1: Total electric industry sales | F1: =SUMIFS('EIA_State Elec Profiles'!C:C,'EIA_State Elec Profiles'!A:A,About!$B$1,'EIA_State Elec Profiles'!B:B,E1) -> 32990570 | H1: EPS Total Demand
A2: Total international imports | B2: Net interstate imports | C2: Total international exports | D2: Net interstate exports | E2: Net Imports/Exports | F2: =SUM(SUMIFS('EIA_State Elec Profiles'!C:C,'EIA_State Elec Profiles'!A:A,About!$B$1,'EIA_State Elec Profiles'!B:B,A2),SUMIFS('EIA_State Elec Profiles'!C:C,'EIA_State Elec Profiles'!A:A,About!$B$1,'EIA_State Elec Profiles'!B:B,B2))-SUM(SUMIFS('EIA_State Elec Profiles'!C:C,'EIA_State Elec Profiles'!A:A,About!$B$1,'EIA_State Elec Profiles'!B:B,C2),SUMIFS('EIA_State Elec Profiles'!C:C,'EIA_State Elec Profiles'!A:A,About!$B$1,'EIA_State Elec Profiles'!B:B,D2)) -> -15060020 | H2: Net imports
C3: Industrial and commercial generation subtotal | D3: Direct use | E3: CHP adjustment | F3: 0
A4: total net generation | E4: In State Generation | F4: =SUM(SUMIFS('EIA_State Elec Profiles'!C:C,'EIA_State Elec Profiles'!A:A,About!$B$1,'EIA_State Elec Profiles'!B:B,A4),SUMIFS('EIA_State Elec Profiles'!C:C,'EIA_State Elec Profiles'!A:A,About!$B$1,'EIA_State Elec Profiles'!B:B,B4))-SUM(SUMIFS('EIA_State Elec Profiles'!C:C,'EIA_State Elec Profiles'!A:A,About!$B$1,'EIA_State Elec Profiles'!B:B,C4),SUMIFS('EIA_State Elec Profiles'!C:C,'EIA_State Elec Profiles'!A:A,About!$B$1,'EIA_State Elec Profiles'!B:B,D4)) -> 50594818 | H4: Net generation
E5: Subtotal | F5: =F1-SUM(F2:F3) -> 48050590 | G5: =F4+F2 -> 35534798
E6: Estimated losses | F6: =SUMIFS('EIA_State Elec Profiles'!C:C,'EIA_State Elec Profiles'!A:A,About!$B$1,'EIA_State Elec Profiles'!B:B,E6) -> 1539325
E7: Unaccounted | F7: =SUMIFS('EIA_State Elec Profiles'!C:C,'EIA_State Elec Profiles'!A:A,About!$B$1,'EIA_State Elec Profiles'!B:B,E7) -> 261228
E8: Estimated losses % | F8: =SUM(F6:F7)/F1 -> 0.054577808 | G8: =F5*(1+F8) -> 50673086
E10: Net generation

Sheet EIA_State Elec Profiles
B1: Table 10. Supply and disposition of electricity, 1990 through 2024
A2: Alabama | B2: Alabama
A3: Alabama | B3: megawatthours
A4: Alabama | B4: Category | C4: Year 2024 | D4: Year 2023 | E4: Year 2022 | F4: Year 2021 | G4: Year 2020 | H4: Year 2019 | I4: Year 2018 | J4: Year 2017 | K4: Year 2016 | L4: Year 2015 | M4: Year 2014 | N4: Year 2013 | O4: Year 2012 | P4: Year 2011 | Q4: Year 2010 | R4: Year 2009 | S4: Year 2008 | T4: Year 2007 | U4: Year 2006 | V4: Year 2005 | W4: Year 2004 | X4: Year 2003 | Y4: Year 2002 | Z4: Year 2001 | AA4: Year 2000 | AB4: Year 1999 | AC4: Year 1998 | AD4: Year 1997 | AE4: Year 1996 | AF4: Year 1995 | AG4: Year 1994 | AH4: Year 1993 | AI4: Year 1992 | AJ4: Year 1991 | AK4: Year 1990
A5: Alabama | B5: Supply
A6: Alabama | B6: Generation
A7: Alabama | B7: ..Electric utilities | C7: 104914796 | D7: 97500930 | E7: 103494925 | F7: 106804340 | G7: 102357230 | H7: 102180494 | I7: 102665414 | J7: 101709381 | K7: 97991203 | L7: 107868476 | M7: 112340555 | N7: 115027021 | O7: 108425247 | P7: 118834736 | Q7: 122766490 | R7: 118781555 | S7: 128054895 | T7: 124273167 | U7: 124365180 | V7: 126303893 | W7: 124554606 | X7: 126845720 | Y7: 123739223 | Z7: 118744284 | AA7: 118037076 | AB7: 113908581 | AC7: 113393840 | AD7: 113683627 | AE7: 115093211 | AF7: 99589284 | AG7: 95171057 | AH7: 94123557 | AI7: 90792233 | AJ7: 85050801 | AK7: 76231696
A8: Alabama | B8: ..Independent power producers | C8: 32981091 | D8: 31787099 | E8: 31750036 | F8: 26941613 | G8: 27553362 | H8: 32439211 | I8: 32906202 | J8: 29571872 | K8: 35632171 | L8: 35059831 | M8: 29036222 | N8: 27383743 | O8: 35812766 | P8: 29424158 | Q8: 20923024 | R8: 15302426 | S8: 10683147 | T8: 9201656 | U8: 7103396 | V8: 4821000 | W8: 6127041 | X8: 4064709 | Y8: 2357413 | Z8: 44733 | AA8: 42291 | AB8: 48901 | AC8: 4410 | AD8: 4852 | AE8: 5847 | AF8: 7278 | AG8: 15314 | AH8: 10989 | AI8: 25233 | AJ8: 25233 | AK8: 27936
A9: Alabama | B9: ..Combined heat and power, electric | C9: 0 | D9: 5422456 | E9: 5032840 | F9: 4031284 | G9: 2848326 | H9: 3157136 | I9: 4864301 | J9: 4245625 | K9: 4506703 | L9: 5332204 | M9: 4125833 | N9: 4014623 | O9: 4393369 | P9: 3773959 | Q9: 4243149 | R9: 4605863 | S9: 2569428 | T9: 5705071 | U9: 4683179 | V9: 2173642 | W9: 1445678 | X9: 1310750 | Y9: 1458857 | Z9: 698013 | AA9: 549830 | AB9: 746941 | AC9: 842095 | AD9: 683325 | AE9: 670529 | AF9: 647195 | AG9: 692589 | AH9: 787844 | AI9: 778496 | AJ9: 786954 | AK9: 665814
A10: Alabama | B10: Electric power sector generation subtotal | C10: 137895887 | D10: 134710486 | E10: 140277801 | F10: 137777237 | G10: 132758918 | H10: 137776841 | I10: 140435917 | J10: 135526878 | K10: 138130077 | L10: 148260511 | M10: 145502610 | N10: 146425387 | O10: 148631382 | P10: 152032853 | Q10: 147932663 | R10: 138689844 | S10: 141307470 | T10: 139179894 | U10: 136151755 | V10: 133298535 | W10: 132127325 | X10: 132221179 | Y10: 127555493 | Z10: 119487030 | AA10: 118629197 | AB10: 114704423 | AC10: 114240345 | AD10: 114371803 | AE10: 115769588 | AF10: 100243757 | AG10: 95878960 | AH10: 94922390 | AI10: 91595962 | AJ10: 85862988 | AK10: 76925446
A11: Alabama | B11: ..Combined heat and power, commercial | C11: 0 | D11: 0 | E11: 0 | F11: 0 | G11: 0 | H11: 0 | I11: 0 | J11: 0 | K11: 0 | L11: 0 | M11: 0 | N11: 0 | O11: 0 | P11: 0 | Q11: 0 | R11: 0 | S11: 0 | T11: 0 | U11: 0 | V11: 0 | W11: 0 | X11: 0 | Y11: 0 | Z11: 0 | AA11: 0 | AB11: 0 | AC11: 0 | AD11: 0 | AE11: 0 | AF11: 0 | AG11: 0 | AH11: 0 | AI11: 0 | AJ11: 0 | AK11: 0
A12: Alabama | B12: ..Combined heat and power, industrial | C12: 5025329 | D12: 4724524 | E12: 4511092 | F12: 4956093 | G12: 4788458 | H12: 4902592 | I12: 4622077 | J12: 4437372 | K12: 4255021 | L12: 4216916 | M12: 3837837 | N12: 4147537 | O12: 4247306 | P12: 4306357 | Q12: 4217849 | R12: 4565712 | S12: 4562425 | T12: 4646377 | U12: 4743686 | V12: 4650046 | W12: 5227446 | X12: 5266043 | Y12: 5365177 | Z12: 5858092 | AA12: 5776146 | AB12: 5953085 | AC12: 5621779 | AD12: 5170528 | AE12: 5703321 | AF12: 4945610 | AG12: 4885299 | AH12: 4414607 | AI12: 3638459 | AJ12: 2923624 | AK12: 2726687
A13: Alabama | B13: Industrial and commercial generation subtotal | C13: 5025329 | D13: 4724524 | E13: 4511092 | F13: 4956093 | G13: 4788458 | H13: 4902592 | I13: 4622077 | J13: 4437372 | K13: 4255021 | L13: 4216916 | M13: 3837837 | N13: 4147537 | O13: 4247306 | P13: 4306357 | Q13: 4217849 | R13: 4565712 | S13: 4562425 | T13: 4646377 | U13: 4743686 | V13: 4650046 | W13: 5227446 | X13: 5266043 | Y13: 5365177 | Z13: 5858092 | AA13: 5776146 | AB13: 5953085 | AC13: 5621779 | AD13: 5170528 | AE13: 5703321 | AF13: 4945610 | AG13: 4885299 | AH13: 4414607 | AI13: 3638459 | AJ13: 2923624 | AK13: 2726687
A14: Alabama | B14: Total net generation | C14: 142921216 | D14: 139435010 | E14: 144788893 | F14: 142733330 | G14: 137547377 | H14: 142679433 | I14: 145057994 | J14: 139964250 | K14: 142385098 | L14: 152477427 | M14: 149340447 | N14: 150572924 | O14: 152878688 | P14: 156339210 | Q14: 152150512 | R14: 143255556 | S14: 145869895 | T14: 143826271 | U14: 140895441 | V14: 137948581 | W14: 137354771 | X14: 137487222 | Y14: 132920670 | Z14: 125345122 | AA14: 124405343 | AB14: 120657508 | AC14: 119862125 | AD14: 119542331 | AE14: 121472909 | AF14: 105189368 | AG14: 100764259 | AH14: 99336997 | AI14: 95234421 | AJ14: 88786611 | AK14: 79652133
A15: Alabama | B15: Total international imports | C15: 0 | D15: 0 | E15: 0 | F15: 0 | G15: 0 | H15: 0 | I15: 0 | J15: 0 | K15: 0 | L15: 0 | M15: 0 | N15: 0 | O15: 0 | P15: 0 | Q15: 0 | R15: 0 | S15: 0 | T15: 0 | U15: 0 | V15: 0 | W15: 0 | X15: 0 | Y15: 0 | Z15: 0 | AA15: 0 | AB15: 0 | AC15: 0 | AD15: 0 | AE15: 0 | AF15: 0 | AG15: 0 | AH15: 0 | AI15: 0 | AJ15: 0 | AK15: 0
A16: Alabama | B16: Net interstate imports | C16: 0 | D16: 0 | E16: 0 | F16: 0 | G16: 0 | H16: 0 | I16: 0 | J16: 0 | K16: 0 | L16: 0 | M16: 0 | N16: 0 | O16: 0 | P16: 0 | Q16: 0 | R16: 0 | S16: 0 | T16: 0 | U16: 0 | V16: 0 | W16: 0 | X16: 0 | Y16: 0 | Z16: 0 | AA16: 0 | AB16: 0 | AC16: 0 | AD16: 0 | AE16: 0 | AF16: 0 | AG16: 0 | AH16: 0 | AI16: 0 | AJ16: 0 | AK16: 0
A17: Alabama | B17: Total supply | C17: 142921216 | D17: 139435010 | E17: 144788893 | F17: 142733330 | G17: 137547377 | H17: 142679433 | I17: 145057994 | J17: 139964250 | K17: 142385098 | L17: 152477427 | M17: 149340447 | N17: 150572924 | O17: 152878688 | P17: 156339210 | Q17: 152150512 | R17: 143255556 | S17: 145869895 | T17: 143826271 | U17: 140895441 | V17: 137948581 | W17: 137354771 | X17: 137487222 | Y17: 132920670 | Z17: 125345122 | AA17: 124405343 | AB17: 120657508 | AC17: 119862125 | AD17: 119542331 | AE17: 121472909 | AF17: 105189368 | AG17: 100764259 | AH17: 99336997 | AI17: 95234421 | AJ17: 88786611 | AK17: 79652133
A18: Alabama | B18: Disposition
A19: Alabama | B19: Sales to ultimate customers
A20: Alabama | B20: ..Full service providers | C20: 87505983 | D20: 84864833 | E20: 87008967 | F20: 85567957 | G20: 83378325 | H20: 88076945 | I20: 90262480 | J20: 86240854 | K20: 88225141 | L20: 88845543 | M20: 90493727 | N20: 87852107 | O20: 86182548 | P20: 88536501 | Q20: 90862645 | R20: 82427315 | S20: 89281681 | T20: 91828464 | U20: 90677695 | V20: 89201620 | W20: 86870519 | X20: 83844220 | Y20: 83067078 | Z20: 79358258 | AA20: 83524220 | AB20: 80401079 | AC20: 79173033 | AD20: 74553869 | AE20: 73104419 | AF20: 70006764 | AG20: 67580676 | AH20: 65057675 | AI20: 62166661 | AJ20: 61227325 | AK20: 59925613
A21: Alabama | B21: ..Energy-only providers | C21: 0 | D21: 0 | E21: 0 | F21: 0 | G21: 0 | H21: 0 | I21: 0 | J21: 0 | K21: 0 | L21: 0 | M21: 0 | N21: 0 | O21: 0 | P21: 0 | Q21: 0 | R21: 0 | S21: 0 | T21: 0 | U21: 0 | V21: 0 | W21: 0 | X21: 0 | Y21: 0 | Z21: 0 | AA21: 0 | AB21: 0 | AC21: 0 | AD21: 0 | AE21: 0 | AF21: 0 | AG21: 0 | AH21: 0 | AI21: 0 | AJ21: 0 | AK21: 0
A22: Alabama | B22: ..Facility direct sales | C22: 16949 | D22: 15526 | E22: 18578 | F22: 17209 | G22: 17280 | H22: 18167 | I22: 17976 | J22: 876 | K22: 0 | L22: 0 | M22: 0 | N22: 0 | O22: 0 | P22: 458868 | Q22: 0 | R22: 417287 | S22: 425598 | T22: 0 | U22: 0 | V22: 0 | W22: 0 | X22: 0 | Y22: 0 | Z22: 0 | AA22: 0 | AB22: 0 | AC22: 0 | AD22: 0 | AE22: 0 | AF22: 0 | AG22: 0 | AH22: 0 | AI22: 0 | AJ22: 0 | AK22: 0
A23: Alabama | B23: Total electric industry sales | C23: 87522932 | D23: 84880359 | E23: 87027545 | F23: 85585166 | G23: 83395605 | H23: 88095112 | I23: 90280456 | J23: 86241730 | K23: 88225141 | L23: 88845543 | M23: 90493727 | N23: 87852107 | O23: 86182548 | P23: 88995369 | Q23: 90862645 | R23: 82844602 | S23: 89707279 | T23: 91828464 | U23: 90677695 | V23: 89201620 | W23: 86870519 | X23: 83844220 | Y23: 83067078 | Z23: 79358258 | AA23: 83524220 | AB23: 80401079 | AC23: 79173033 | AD23: 74553869 | AE23: 73104419 | AF23: 70006764 | AG23: 67580676 | AH23: 65057675 | AI23: 62166661 | AJ23: 61227325 | AK23: 59925613
A24: Alabama | B24: Direct use | C24: 5244160 | D24: 5491093 | E24: 4896466 | F24: 5344337 | G24: 5110676 | H24: 5159502 | I24: 5037015 | J24: 4928261 | K24: 4586964 | L24: 4551804 | M24: 5000379 | N24: 4608062 | O24: 5286916 | P24: 5157007 | Q24: 5007573 | R24: 4827750 | S24: 4726425 | T24: 4620025 | U24: 6209972 | V24: 3540326 | W24: 6487857 | X24: 6481099 | Y24: 6399833 | Z24: 6263673 | AA24: 6277371 | AB24: 6668570 | AC24: 6441674 | AD24: 5827652 | AE24: 6339694 | AF24: 5553211 | AG24: 5524010 | AH24: 5174420 | AI24: 4379722 | AJ24: 3667285 | AK24: 3379559
A25: Alabama | B25: Total international exports | C25: 0 | D25: 0 | E25: 0 | F25: 0 | G25: 0 | H25: 0 | I25: 0 | J25: 0 | K25: 0 | L25: 0 | M25: 0 | N25: 0 | O25: 0 | P25: 0 | Q25: 0 | R25: 0 | S25: 0 | T25: 0 | U25: 0 | V25: 0 | W25: 0 | X25: 0 | Y25: 0 | Z25: 0 | AA25: 0 | AB25: 0 | AC25: 0 | AD25: 0 | AE25: 0 | AF25: 0 | AG25: 0 | AH25: 0 | AI25: 0 | AJ25: 0 | AK25: 0
A26: Alabama | B26: Estimated losses | C26: 4083781 | D26: 3759111 | E26: 4707447 | F26: 4026481 | G26: 4644657 | H26: 4776859 | I26: 4656454 | J26: 4691415 | K26: 4604565 | L26: 4432118 | M26: 4712003 | N26: 4719383 | O26: 4667126 | P26: 5499347 | Q26: 5613291 | R26: 5273674 | S26: 5714398 | T26: 5812051 | U26: 5879439 | V26: 5961856 | W26: 6365524 | X26: 6156524 | Y26: 6230830 | Z26: 6206090 | AA26: 6496787 | AB26: 6307636 | AC26: 5629812 | AD26: 5621134 | AE26: 5674489 | AF26: 5343282 | AG26: 5133856 | AH26: 5206804 | AI26: 4914509 | AJ26: 4701328 | AK26: 4549600
A27: Alabama | B27: Unaccounted | C27: 693029 | D27: 430643 | E27: -157254 | F27: 546608 | G27: -125281 | H27: 219933 | I27: 564398 | J27: 601020 | K27: 1094734 | L27: 1384712 | M27: 1170058 | N27: 1325273 | O27: 1473752 | P27: 563791 | Q27: 797298 | R27: 746799 | S27: 1171515 | T27: 1463528 | U27: 0 | V27: 0 | W27: 0 | X27: 0 | Y27: 0 | Z27: 0 | AA27: 0 | AB27: 0 | AC27: 0 | AD27: 0 | AE27: 0 | AF27: 0 | AG27: 0 | AH27: 0 | AI27: 0 | AJ27: 0 | AK27: 0
A28: Alabama | B28: Net interstate exports | C28: 45377314 | D28: 44873804 | E28: 48314688 | F28: 47230739 | G28: 44521720 | H28: 44428027 | I28: 44519671 | J28: 43501825 | K28: 43873694 | L28: 53263250 | M28: 47964280 | N28: 52068099 | O28: 55268345 | P28: 56123696 | Q28: 49869705 | R28: 49562730 | S28: 44550279 | T28: 40102203 | U28: 39995621 | V28: 38526487 | W28: 39822338 | X28: 44129506 | Y28: 40454195 | Z28: 37513134 | AA28: 30759648 | AB28: 30252413 | AC28: 31423683 | AD28: 35978305 | AE28: 39351180 | AF28: 26383323 | AG28: 24963948 | AH28: 26034116 | AI28: 25273664 | AJ28: 20206571 | AK28: 12515999
A29: Alabama | B29: Total disposition | C29: 142921216 | D29: 139435010 | E29: 144788893 | F29: 142733330 | G29: 137547377 | H29: 142679433 | I29: 145057994 | J29: 139964250 | K29: 142385098 | L29: 152477427 | M29: 149340447 | N29: 150572924 | O29: 152878688 | P29: 156339210 | Q29: 152150512 | R29: 143255556 | S29: 145869895 | T29: 143826271 | U29: 140895441 | V29: 137948581 | W29: 137354771 | X29: 137487222 | Y29: 132920670 | Z29: 125345122 | AA29: 124405343 | AB29: 120657508 | AC29: 119862125 | AD29: 119542331 | AE29: 121472909 | AF29: 105189368 | AG29: 100764259 | AH29: 99336997 | AI29: 95234421 | AJ29: 88786611 | AK29: 79652133
A30: Alabama | B30: Net interstate trade | C30: 45377314 | D30: 44873804 | E30: 48314688 | F30: 47230739 | G30: 44521720 | H30: 44428027 | I30: 44519671 | J30: 43501825 | K30: 43873694 | L30: 53263250 | M30: 47964280 | N30: 52068099 | O30: 55268345 | P30: 56123696 | Q30: 49869705 | R30: 49562730 | S30: 44550279 | T30: 40102203 | U30: 39995621 | V30: 38526487 | W30: 39822338 | X30: 44129506 | Y30: 40454195 | Z30: 37513134 | AA30: 30759648 | AB30: 30252413 | AC30: 31423683 | AD30: 35978305 | AE30: 39351180 | AF30: 26383323 | AG30: 24963948 | AH30: 26034116 | AI30: 25273664 | AJ30: 20206571 | AK30: 12515999
A31: Alabama | B31: Net trade index (ratio) | C31: 1.47 | D31: 1.47 | E31: 1.5 | F31: 1.49 | G31: 1.48 | H31: 1.45 | I31: 1.44 | J31: 1.45 | K31: 1.45 | L31: 1.54 | M31: 1.47 | N31: 1.53 | O31: 1.57 | P31: 1.56 | Q31: 1.49 | R31: 1.53 | S31: 1.44 | T31: 1.39 | U31: 1.4 | V31: 1.39 | W31: 1.41 | X31: 1.47 | Y31: 1.44 | Z31: 1.43 | AA31: 1.33 | AB31: 1.33 | AC31: 1.36 | AD31: 1.43 | AE31: 1.48 | AF31: 1.33 | AG31: 1.33 | AH31: 1.36 | AI31: 1.36 | AJ31: 1.29 | AK31: 1.19
A32: Alaska | B32: Alaska
A33: Alaska | B33: megawatthours
A34: Alaska | B34: Category | C34: Year 2024 | D34: Year 2023 | E34: Year 2022 | F34: Year 2021 | G34: Year 2020 | H34: Year 2019 | I34: Year 2018 | J34: Year 2017 | K34: Year 2016 | L34: Year 2015 | M34: Year 2014 | N34: Year 2013 | O34: Year 2012 | P34: Year 2011 | Q34: Year 2010 | R34: Year 2009 | S34: Year 2008 | T34: Year 2007 | U34: Year 2006 | V34: Year 2005 | W34: Year 2004 | X34: Year 2003 | Y34: Year 2002 | Z34: Year 2001 | AA34: Year 2000 | AB34: Year 1999 | AC34: Year 1998 | AD34: Year 1997 | AE34: Year 1996 | AF34: Year 1995 | AG34: Year 1994 | AH34: Year 1993 | AI34: Year 1992 | AJ34: Year 1991 | AK34: Year 1990
A35: Alaska | B35: Supply
A36: Alaska | B36: Generation
A37: Alaska | B37: ..Electric utilities | C37: 6020426 | D37: 6022622 | E37: 6032387 | F37: 5910717 | G37: 5596841 | H37: 5447446 | I37: 5575087 | J37: 5822931 | K37: 5649381 | L37: 5746428 | M37: 5509991 | N37: 5851727 | O37: 6361802 | P37: 6273844 | Q37: 6205050 | R37: 6166762 | S37: 6262148 | T37: 6146078 | U37: 6068520 | V37: 5946148 | W37: 5866420 | X37: 5673462 | Y37: 5471990 | Z37: 5416191 | AA37: 4937687 | AB37: 4609315 | AC37: 4590270 | AD37: 5108003 | AE37: 4982268 | AF37: 4846922 | AG37: 4762116 | AH37: 4581047 | AI37: 4167054 | AJ37: 4286431 | AK37: 4493024
A38: Alaska | B38: ..Independent power producers | C38: 61020 | D38: 50309 | E38: 58398 | F38: 45413 | G38: 53831 | H38: 55971 | I38: 56327 | J38: 50322 | K38: 60468 | L38: 54562 | M38: 52313 | N38: 46384 | O38: 18124 | P38: 0 | Q38: 0 | R38: 0 | S38: 0 | T38: 80133 | U38: 0 | V38: 0 | W38: 0 | X38: 0 | Y38: 0 | Z38: 0 | AA38: 0 | AB38: 0 | AC38: 0 | AD38: 0 | AE38: 0 | AF38: 0 | AG38: 0 | AH38: 0 | AI38: 0 | AJ38: 0 | AK38: 0
A39: Alaska | B39: ..Combined heat and power, electric | C39: 121336 | D39: 143360 | E39: 149377 | F39: 177115 | G39: 188212 | H39: 186691 | I39: 177819 | J39: 180906 | K39: 191982 | L39: 198296 | M39: 191062 | N39: 187843 | O39: 201405 | P39: 209150 | Q39: 204196 | R39: 209379 | S39: 177106 | T39: 210155 | U39: 187376 | V39: 173942 | W39: 182145 | X39: 162478 | Y39: 243668 | Z39: 237307 | AA39: 223962 | AB39: 226975 | AC39: 211373 | AD39: 0 | AE39: 0 | AF39: 0 | AG39: 0 | AH39: 0 | AI39: 0 | AJ39: 0 | AK39: 0
A40: Alaska | B40: Electric power sector generation subtotal | C40: 6202782 | D40: 6216291 | E40: 6240162 | F40: 6133245 | G40: 5838884 | H40: 5690108 | I40: 5809233 | J40: 6054159 | K40: 5901831 | L40: 5999286 | M40: 5753366 | N40: 6085954 | O40: 6581331 | P40: 6482994 | Q40: 6409246 | R40: 6376141 | S40: 6439254 | T40: 6436366 | U40: 6255896 | V40: 6120090 | W40: 6048565 | X40: 5835940 | Y40: 5715658 | Z40: 5653498 | AA40: 5161649 | AB40: 4836290 | AC40: 4801643 | AD40: 5108003 | AE40: 4982268 | AF40: 4846922 | AG40: 4762116 | AH40: 4581047 | AI40: 4167054 | AJ40: 4286431 | AK40: 4493024
...

Sheet BTaDLP
A1: Year | B1: 2020 | C1: 2021 | D1: 2022 | E1: 2023 | F1: 2024 | G1: 2025 | H1: 2026 | I1: 2027 | J1: 2028 | K1: 2029 | L1: 2030 | M1: 2031 | N1: 2032 | O1: 2033 | P1: 2034 | Q1: 2035 | R1: 2036 | S1: 2037 | T1: 2038 | U1: 2039 | V1: 2040 | W1: 2041 | X1: 2042 | Y1: 2043 | Z1: 2044 | AA1: 2045 | AB1: 2046 | AC1: 2047 | AD1: 2048 | AE1: 2049 | AF1: 2050
A2: Trans and Dist Loss Perc (dimensionless) | B2: =calc!F8 -> 0.054577808 | C2: =B2 -> 0.054577808 | D2: =C2 -> 0.054577808 | E2: =D2 -> 0.054577808 | F2: =E2 -> 0.054577808 | G2: =F2 -> 0.054577808 | H2: =G2 -> 0.054577808 | I2: =H2 -> 0.054577808 | J2: =I2 -> 0.054577808 | ... AF2: =AE2 -> 0.054577808
