Workbook

Sheet About
A1: BMRESP BAU Minimum Required EV Sales Percentage | B1: West Virginia | C1: 45233
A3: Source: | B3: California Air Resources Board (CARB)
B4: California's Advanced Clean Cars Midterm Review Report
B5: Techical report: https://www.arb.ca.gov/msprog/acc/mtr/acc_mtr_finalreport_full.pdf
B6: Data: https://www.arb.ca.gov/msprog/zevprog/zevcalculator/zevcalculator_2017.xlsx
A8: Notes
A9: California Zero Emission Vehicle (ZEV) mandate calls for 15% of sales to be zero emission vehicles by 2025. The ZEV mandate reaches a plateau in that year, and so the required percentage is held constant thereafter.
A10: However, the number of full ZEVs required is expected to be substantially less than 15% in 2020.
A11: We pull data from CARB's anticipated compliance pathway to represent the required ZEV uptake expected from the mandate.
A13: "The reduction in the estimated effect of the standard is primarily due to two factors: the range of EVs has increased far faster than anticipated (increasing the ZEV credits earned per vehicle), and the current stockpile of ZEV credits from early compliance with the regulation which can be used in place of future ZEV sales."
A15: http://blog.ucsusa.org/dave-reichmuth/what-will-it-take-for-automakers-to-meet-californias-ev-requirements-not-as-much-as-you-might-think
A19: Waiver states (as of August 2019)
A20: Connecticut, Maine, Maryland, Massachusetts, New Jersey, New York, Oregon, Rhode Island, Vermont, Colorado, Washington
A21: https://www.edf.org/media/colorado-becomes-first-state-central-us-adopt-zero-emission-vehicle-standards

Sheet ZEV Waiver States
A1: =About!B1 -> West Virginia | B1: <- State
B2: 2016 | C2: 2017 | D2: 2018 | E2: 2019 | F2: 2020 | G2: 2021 | H2: 2022 | I2: 2023 | J2: 2024 | K2: 2025 | L2: 2026 | M2: 2027 | N2: 2028 | O2: 2029 | P2: 2030 | Q2: 2031 | R2: 2032 | S2: 2033 | T2: 2034 | U2: 2035 | V2: 2036 | W2: 2037 | X2: 2038 | Y2: 2039 | Z2: 2040 | AA2: 2041 | AB2: 2042 | AC2: 2043 | AD2: 2044 | AE2: 2045 | AF2: 2046 | AG2: 2047 | AH2: 2048 | AI2: 2049 | AJ2: 2050
A3: Lookup LDV | B3: =IF(SUMIFS($B$9:$B$58,$A$9:$A$58,$A$1)=1,B5,B6) -> 0 | C3: =IF(SUMIFS($B$9:$B$58,$A$9:$A$58,$A$1)=1,C5,C6) -> 0 | D3: =IF(SUMIFS($B$9:$B$58,$A$9:$A$58,$A$1)=1,D5,D6) -> 0 | E3: =IF(SUMIFS($B$9:$B$58,$A$9:$A$58,$A$1)=1,E5,E6) -> 0 | F3: =IF(SUMIFS($B$9:$B$58,$A$9:$A$58,$A$1)=1,F5,F6) -> 0 | G3: =IF(SUMIFS($B$9:$B$58,$A$9:$A$58,$A$1)=1,G5,G6) -> 0 | H3: =IF(SUMIFS($B$9:$B$58,$A$9:$A$58,$A$1)=1,H5,H6) -> 0 | I3: =IF(SUMIFS($B$9:$B$58,$A$9:$A$58,$A$1)=1,I5,I6) -> 0 | ... AJ3: =IF(SUMIFS($B$9:$B$58,$A$9:$A$58,$A$1)=1,AJ5,AJ6) -> 0
A5: LDVs ZEV | B5: 0 | C5: 0 | D5: 0.02335518 | E5: 0.030832276 | F5: 0.042396225 | G5: 0.05069981 | H5: 0.056578479 | I5: 0.063298146 | J5: 0.069598265 | K5: 0.075536124 | L5: 0.075536124 | M5: 0.075536124 | N5: 0.075536124 | O5: 0.075536124 | P5: 0.075536124 | Q5: 0.075536124 | R5: 0.075536124 | S5: 0.075536124 | T5: 0.075536124 | U5: 0.075536124 | V5: 0.075536124 | W5: 0.075536124 | X5: 0.075536124 | Y5: 0.075536124 | Z5: 0.075536124 | AA5: 0.075536124 | AB5: 0.075536124 | AC5: 0.075536124 | AD5: 0.075536124 | AE5: 0.075536124 | AF5: 0.075536124 | AG5: 0.075536124 | AH5: 0.075536124 | AI5: 0.075536124 | AJ5: 0.075536124
A6: LDV no ZEV | B6: 0 | C6: 0 | D6: 0 | E6: 0 | F6: 0 | G6: 0 | H6: 0 | I6: 0 | J6: 0 | K6: 0 | L6: 0 | M6: 0 | N6: 0 | O6: 0 | P6: 0 | Q6: 0 | R6: 0 | S6: 0 | T6: 0 | U6: 0 | V6: 0 | W6: 0 | X6: 0 | Y6: 0 | Z6: 0 | AA6: 0 | AB6: 0 | AC6: 0 | AD6: 0 | AE6: 0 | AF6: 0 | AG6: 0 | AH6: 0 | AI6: 0 | AJ6: 0
A8: State Name | B8: ZEV?
A9: Alabama
A10: Alaska | E10: ZEV Waiver States
A11: Arizona | E11: Connecticut, Maine, Maryland, Massachusetts, New Jersey, New York, Oregon, Rhode Island, Vermont, Colorado, Washington
A12: Arkansas
A13: California | B13: 1
A14: Colorado | B14: 1
A15: Connecticut | B15: 1
A16: Delaware
A17: Florida
A18: Georgia
A19: Hawaii
A20: Idaho
A21: Illinois
A22: Indiana
A23: Iowa
A24: Kansas
A25: Kentucky
A26: Louisiana
A27: Maine | B27: 1
A28: Maryland | B28: 1
A29: Massachusetts | B29: 1
A30: Michigan
A31: Minnesota
A32: Mississippi
A33: Missouri
A34: Montana
A35: Nebraska
A36: Nevada
A37: New Hampshire
A38: New Jersey | B38: 1
A39: New Mexico
A40: New York | B40: 1
A41: North Carolina
A42: North Dakota
...

Sheet IRA Calculations
A1: Summary
A2: 13401 | B2: Clean Vehicle Credit | C2: Transportation
A5: PRE IRA
B6: 2016 | C6: 2017 | D6: 2018 | E6: 2019 | F6: 2020 | G6: 2021 | H6: 2022 | I6: 2023 | J6: 2024 | K6: 2025 | L6: 2026 | M6: 2027 | N6: 2028 | O6: 2029 | P6: 2030 | Q6: 2031 | R6: 2032 | S6: 2033 | T6: 2034 | U6: 2035 | V6: 2036 | W6: 2037 | X6: 2038 | Y6: 2039 | Z6: 2040 | AA6: 2041 | AB6: 2042 | AC6: 2043 | AD6: 2044 | AE6: 2045 | AF6: 2046 | AG6: 2047 | AH6: 2048 | AI6: 2049 | AJ6: 2050
A7: LDVs | B7: ='ZEV Waiver States'!B3 -> 0 | C7: ='ZEV Waiver States'!C3 -> 0 | D7: ='ZEV Waiver States'!D3 -> 0 | E7: ='ZEV Waiver States'!E3 -> 0 | F7: ='ZEV Waiver States'!F3 -> 0 | G7: ='ZEV Waiver States'!G3 -> 0 | H7: ='ZEV Waiver States'!H3 -> 0 | I7: ='ZEV Waiver States'!I3 -> 0 | ... AJ7: ='ZEV Waiver States'!AJ3 -> 0
A8: HDVs | B8: 0 | C8: 0 | D8: 0 | E8: 0 | F8: 0 | G8: 0 | H8: 0 | I8: 0 | J8: 0 | K8: 0 | L8: 0 | M8: 0 | N8: 0 | O8: 0 | P8: 0 | Q8: 0 | R8: 0 | S8: 0 | T8: 0 | U8: 0 | V8: 0 | W8: 0 | X8: 0 | Y8: 0 | Z8: 0 | AA8: 0 | AB8: 0 | AC8: 0 | AD8: 0 | AE8: 0 | AF8: 0 | AG8: 0 | AH8: 0 | AI8: 0 | AJ8: 0
A9: aircraft | B9: 0 | C9: 0 | D9: 0 | E9: 0 | F9: 0 | G9: 0 | H9: 0 | I9: 0 | J9: 0 | K9: 0 | L9: 0 | M9: 0 | N9: 0 | O9: 0 | P9: 0 | Q9: 0 | R9: 0 | S9: 0 | T9: 0 | U9: 0 | V9: 0 | W9: 0 | X9: 0 | Y9: 0 | Z9: 0 | AA9: 0 | AB9: 0 | AC9: 0 | AD9: 0 | AE9: 0 | AF9: 0 | AG9: 0 | AH9: 0 | AI9: 0 | AJ9: 0
A10: rail | B10: 0 | C10: 0 | D10: 0 | E10: 0 | F10: 0 | G10: 0 | H10: 0 | I10: 0 | J10: 0 | K10: 0 | L10: 0 | M10: 0 | N10: 0 | O10: 0 | P10: 0 | Q10: 0 | R10: 0 | S10: 0 | T10: 0 | U10: 0 | V10: 0 | W10: 0 | X10: 0 | Y10: 0 | Z10: 0 | AA10: 0 | AB10: 0 | AC10: 0 | AD10: 0 | AE10: 0 | AF10: 0 | AG10: 0 | AH10: 0 | AI10: 0 | AJ10: 0
A11: ships | B11: 0 | C11: 0 | D11: 0 | E11: 0 | F11: 0 | G11: 0 | H11: 0 | I11: 0 | J11: 0 | K11: 0 | L11: 0 | M11: 0 | N11: 0 | O11: 0 | P11: 0 | Q11: 0 | R11: 0 | S11: 0 | T11: 0 | U11: 0 | V11: 0 | W11: 0 | X11: 0 | Y11: 0 | Z11: 0 | AA11: 0 | AB11: 0 | AC11: 0 | AD11: 0 | AE11: 0 | AF11: 0 | AG11: 0 | AH11: 0 | AI11: 0 | AJ11: 0
A12: motorbikes | B12: 0 | C12: 0 | D12: 0 | E12: 0 | F12: 0 | G12: 0 | H12: 0 | I12: 0 | J12: 0 | K12: 0 | L12: 0 | M12: 0 | N12: 0 | O12: 0 | P12: 0 | Q12: 0 | R12: 0 | S12: 0 | T12: 0 | U12: 0 | V12: 0 | W12: 0 | X12: 0 | Y12: 0 | Z12: 0 | AA12: 0 | AB12: 0 | AC12: 0 | AD12: 0 | AE12: 0 | AF12: 0 | AG12: 0 | AH12: 0 | AI12: 0 | AJ12: 0
A14: RMI analysis on EV growth w/ IRA credits
A15: Weighted average BEV sales share | B15: 2022 | C15: 2023 | D15: 2024 | E15: 2025 | F15: 2026 | G15: 2027 | H15: 2028 | I15: 2029 | J15: 2030 | K15: 2031 | L15: 2032 | M15: 2033 | N15: 2034 | O15: 2035 | P15: 2036 | Q15: 2037 | R15: 2038 | S15: 2039 | T15: 2040 | U15: 2041 | V15: 2042 | W15: 2043 | X15: 2044 | Y15: 2045 | Z15: 2046 | AA15: 2047 | AB15: 2048 | AC15: 2049 | AD15: 2050
A16: Without IRA | B16: 0.05 | C16: 0.07 | D16: 0.1 | E16: 0.14 | F16: 0.19 | G16: 0.24 | H16: 0.3 | I16: 0.36 | J16: 0.43 | K16: 0.48 | L16: 0.52
A17: With IRA - High | B17: 0.05 | C17: 0.1 | D17: 0.15 | E17: 0.21 | F17: 0.28 | G17: 0.37 | H17: 0.46 | I17: 0.55 | J17: 0.64 | K17: 0.71 | L17: 0.76
A18: With IRA - Med | B18: 0.05 | C18: 0.09 | D18: 0.11 | E18: 0.16 | F18: 0.23 | G18: 0.31 | H18: 0.39 | I18: 0.47 | J18: 0.55 | K18: 0.61 | L18: 0.67
A19: With IRA - Low | B19: 0.05 | C19: 0.08 | D19: 0.1 | E19: 0.14 | F19: 0.19 | G19: 0.25 | H19: 0.32 | I19: 0.39 | J19: 0.46 | K19: 0.52 | L19: 0.57
A20: Difference | B20: 0 | C20: 0.01 | D20: 0 | E20: 0 | F20: 0 | G20: 0.01 | H20: 0.02 | I20: 0.03 | J20: 0.03 | K20: 0.04 | L20: 0.05 | M20: 0.05 | N20: 0.05 | O20: 0.05 | P20: 0.05 | Q20: 0.05 | R20: 0.05 | S20: 0.05 | T20: 0.05 | U20: 0.05 | V20: 0.05 | W20: 0.05 | X20: 0.05 | Y20: 0.05 | Z20: 0.05 | AA20: 0.05 | AB20: 0.05 | AC20: 0.05 | AD20: 0.05
A23: WITH IRA
B24: 2016 | C24: 2017 | D24: 2018 | E24: 2019 | F24: 2020 | G24: 2021 | H24: 2022 | I24: 2023 | J24: 2024 | K24: 2025 | L24: 2026 | M24: 2027 | N24: 2028 | O24: 2029 | P24: 2030 | Q24: 2031 | R24: 2032 | S24: 2033 | T24: 2034 | U24: 2035 | V24: 2036 | W24: 2037 | X24: 2038 | Y24: 2039 | Z24: 2040 | AA24: 2041 | AB24: 2042 | AC24: 2043 | AD24: 2044 | AE24: 2045 | AF24: 2046 | AG24: 2047 | AH24: 2048 | AI24: 2049 | AJ24: 2050
A25: LDVs | B25: =B7 -> 0 | C25: =C7 -> 0 | D25: =D7 -> 0 | E25: =E7 -> 0 | F25: =F7 -> 0 | G25: =G7 -> 0 | H25: =H7 -> 0 | I25: =I7+C20 -> 0.01 | J25: =J7+D20 -> 0 | K25: =K7+E20 -> 0 | L25: =L7+F20 -> 0 | M25: =M7+G20 -> 0.01 | N25: =N7+H20 -> 0.02 | O25: =O7+I20 -> 0.03 | P25: =P7+J20 -> 0.03 | ... AJ25: =AJ7+AD20 -> 0.05

Sheet BMRESP-passenger
B1: 2016 | C1: 2017 | D1: 2018 | E1: 2019 | F1: 2020 | G1: 2021 | H1: 2022 | I1: 2023 | J1: 2024 | K1: 2025 | L1: 2026 | M1: 2027 | N1: 2028 | O1: 2029 | P1: 2030 | Q1: 2031 | R1: 2032 | S1: 2033 | T1: 2034 | U1: 2035 | V1: 2036 | W1: 2037 | X1: 2038 | Y1: 2039 | Z1: 2040 | AA1: 2041 | AB1: 2042 | AC1: 2043 | AD1: 2044 | AE1: 2045 | AF1: 2046 | AG1: 2047 | AH1: 2048 | AI1: 2049 | AJ1: 2050
A2: LDVs | B2: ='IRA Calculations'!B25 -> 0 | C2: ='IRA Calculations'!C25 -> 0 | D2: ='IRA Calculations'!D25 -> 0 | E2: ='IRA Calculations'!E25 -> 0 | F2: ='IRA Calculations'!F25 -> 0 | G2: ='IRA Calculations'!G25 -> 0 | H2: ='IRA Calculations'!H25 -> 0 | I2: ='IRA Calculations'!I25 -> 0.01 | ... AJ2: ='IRA Calculations'!AJ25 -> 0.05
A3: HDVs | B3: 0 | C3: 0 | D3: 0 | E3: 0 | F3: 0 | G3: 0 | H3: 0 | I3: 0 | J3: 0 | K3: 0 | L3: 0 | M3: 0 | N3: 0 | O3: 0 | P3: 0 | Q3: 0 | R3: 0 | S3: 0 | T3: 0 | U3: 0 | V3: 0 | W3: 0 | X3: 0 | Y3: 0 | Z3: 0 | AA3: 0 | AB3: 0 | AC3: 0 | AD3: 0 | AE3: 0 | AF3: 0 | AG3: 0 | AH3: 0 | AI3: 0 | AJ3: 0
A4: aircraft | B4: 0 | C4: 0 | D4: 0 | E4: 0 | F4: 0 | G4: 0 | H4: 0 | I4: 0 | J4: 0 | K4: 0 | L4: 0 | M4: 0 | N4: 0 | O4: 0 | P4: 0 | Q4: 0 | R4: 0 | S4: 0 | T4: 0 | U4: 0 | V4: 0 | W4: 0 | X4: 0 | Y4: 0 | Z4: 0 | AA4: 0 | AB4: 0 | AC4: 0 | AD4: 0 | AE4: 0 | AF4: 0 | AG4: 0 | AH4: 0 | AI4: 0 | AJ4: 0
A5: rail | B5: 0 | C5: 0 | D5: 0 | E5: 0 | F5: 0 | G5: 0 | H5: 0 | I5: 0 | J5: 0 | K5: 0 | L5: 0 | M5: 0 | N5: 0 | O5: 0 | P5: 0 | Q5: 0 | R5: 0 | S5: 0 | T5: 0 | U5: 0 | V5: 0 | W5: 0 | X5: 0 | Y5: 0 | Z5: 0 | AA5: 0 | AB5: 0 | AC5: 0 | AD5: 0 | AE5: 0 | AF5: 0 | AG5: 0 | AH5: 0 | AI5: 0 | AJ5: 0
A6: ships | B6: 0 | C6: 0 | D6: 0 | E6: 0 | F6: 0 | G6: 0 | H6: 0 | I6: 0 | J6: 0 | K6: 0 | L6: 0 | M6: 0 | N6: 0 | O6: 0 | P6: 0 | Q6: 0 | R6: 0 | S6: 0 | T6: 0 | U6: 0 | V6: 0 | W6: 0 | X6: 0 | Y6: 0 | Z6: 0 | AA6: 0 | AB6: 0 | AC6: 0 | AD6: 0 | AE6: 0 | AF6: 0 | AG6: 0 | AH6: 0 | AI6: 0 | AJ6: 0
A7: motorbikes | B7: 0 | C7: 0 | D7: 0 | E7: 0 | F7: 0 | G7: 0 | H7: 0 | I7: 0 | J7: 0 | K7: 0 | L7: 0 | M7: 0 | N7: 0 | O7: 0 | P7: 0 | Q7: 0 | R7: 0 | S7: 0 | T7: 0 | U7: 0 | V7: 0 | W7: 0 | X7: 0 | Y7: 0 | Z7: 0 | AA7: 0 | AB7: 0 | AC7: 0 | AD7: 0 | AE7: 0 | AF7: 0 | AG7: 0 | AH7: 0 | AI7: 0 | AJ7: 0

Sheet BMRESP-freight
B1: 2016 | C1: 2017 | D1: 2018 | E1: 2019 | F1: 2020 | G1: 2021 | H1: 2022 | I1: 2023 | J1: 2024 | K1: 2025 | L1: 2026 | M1: 2027 | N1: 2028 | O1: 2029 | P1: 2030 | Q1: 2031 | R1: 2032 | S1: 2033 | T1: 2034 | U1: 2035 | V1: 2036 | W1: 2037 | X1: 2038 | Y1: 2039 | Z1: 2040 | AA1: 2041 | AB1: 2042 | AC1: 2043 | AD1: 2044 | AE1: 2045 | AF1: 2046 | AG1: 2047 | AH1: 2048 | AI1: 2049 | AJ1: 2050
A2: LDVs | B2: 0 | C2: 0 | D2: 0 | E2: 0 | F2: 0 | G2: 0 | H2: 0 | I2: 0 | J2: 0 | K2: 0 | L2: 0 | M2: 0 | N2: 0 | O2: 0 | P2: 0 | Q2: 0 | R2: 0 | S2: 0 | T2: 0 | U2: 0 | V2: 0 | W2: 0 | X2: 0 | Y2: 0 | Z2: 0 | AA2: 0 | AB2: 0 | AC2: 0 | AD2: 0 | AE2: 0 | AF2: 0 | AG2: 0 | AH2: 0 | AI2: 0 | AJ2: 0
A3: HDVs | B3: 0 | C3: 0 | D3: 0 | E3: 0 | F3: 0 | G3: 0 | H3: 0 | I3: 0 | J3: 0 | K3: 0 | L3: 0 | M3: 0 | N3: 0 | O3: 0 | P3: 0 | Q3: 0 | R3: 0 | S3: 0 | T3: 0 | U3: 0 | V3: 0 | W3: 0 | X3: 0 | Y3: 0 | Z3: 0 | AA3: 0 | AB3: 0 | AC3: 0 | AD3: 0 | AE3: 0 | AF3: 0 | AG3: 0 | AH3: 0 | AI3: 0 | AJ3: 0
A4: aircraft | B4: 0 | C4: 0 | D4: 0 | E4: 0 | F4: 0 | G4: 0 | H4: 0 | I4: 0 | J4: 0 | K4: 0 | L4: 0 | M4: 0 | N4: 0 | O4: 0 | P4: 0 | Q4: 0 | R4: 0 | S4: 0 | T4: 0 | U4: 0 | V4: 0 | W4: 0 | X4: 0 | Y4: 0 | Z4: 0 | AA4: 0 | AB4: 0 | AC4: 0 | AD4: 0 | AE4: 0 | AF4: 0 | AG4: 0 | AH4: 0 | AI4: 0 | AJ4: 0
A5: rail | B5: 0 | C5: 0 | D5: 0 | E5: 0 | F5: 0 | G5: 0 | H5: 0 | I5: 0 | J5: 0 | K5: 0 | L5: 0 | M5: 0 | N5: 0 | O5: 0 | P5: 0 | Q5: 0 | R5: 0 | S5: 0 | T5: 0 | U5: 0 | V5: 0 | W5: 0 | X5: 0 | Y5: 0 | Z5: 0 | AA5: 0 | AB5: 0 | AC5: 0 | AD5: 0 | AE5: 0 | AF5: 0 | AG5: 0 | AH5: 0 | AI5: 0 | AJ5: 0
A6: ships | B6: 0 | C6: 0 | D6: 0 | E6: 0 | F6: 0 | G6: 0 | H6: 0 | I6: 0 | J6: 0 | K6: 0 | L6: 0 | M6: 0 | N6: 0 | O6: 0 | P6: 0 | Q6: 0 | R6: 0 | S6: 0 | T6: 0 | U6: 0 | V6: 0 | W6: 0 | X6: 0 | Y6: 0 | Z6: 0 | AA6: 0 | AB6: 0 | AC6: 0 | AD6: 0 | AE6: 0 | AF6: 0 | AG6: 0 | AH6: 0 | AI6: 0 | AJ6: 0
A7: motorbikes | B7: 0 | C7: 0 | D7: 0 | E7: 0 | F7: 0 | G7: 0 | H7: 0 | I7: 0 | J7: 0 | K7: 0 | L7: 0 | M7: 0 | N7: 0 | O7: 0 | P7: 0 | Q7: 0 | R7: 0 | S7: 0 | T7: 0 | U7: 0 | V7: 0 | W7: 0 | X7: 0 | Y7: 0 | Z7: 0 | AA7: 0 | AB7: 0 | AC7: 0 | AD7: 0 | AE7: 0 | AF7: 0 | AG7: 0 | AH7: 0 | AI7: 0 | AJ7: 0
