Workbook
Name IQ_CH: 110000
Name IQ_CQ: 5000
Name IQ_CY: 10000
Name IQ_DAILY: 500000
Name IQ_FH: 100000
Name IQ_FQ: 500
Name IQ_FY: 1000
Name IQ_LTM: 2000
Name IQ_MONTH: 15000
Name IQ_NTM: 6000
Name IQ_WEEK: 50000
Name IQ_YTD: 3000

Sheet About
A1: BGDPbES BAU Guaranteed Dispatch Percentage by Electricity Source | B1: West Virginia | C1: 45747 | F1: State | G1: State
B2: =LOOKUP(B1,F2:G51,G2:G51) -> WV | F2: Alabama | G2: AL | H2: =F2&".xlsx" -> Alabama.xlsx
A3: Source: | B3: Petroleum | F3: Alaska | G3: AK | H3: =F3&".xlsx" -> Alaska.xlsx
B4: Weighted Average Expected Capacity Factors (calculated EPS variable) | F4: Arizona | G4: AZ | H4: =F4&".xlsx" -> Arizona.xlsx
F5: Arkansas | G5: AR | H5: =F5&".xlsx" -> Arkansas.xlsx
F6: California | G6: CA | H6: =F6&".xlsx" -> California.xlsx
F7: Colorado | G7: CO | H7: =F7&".xlsx" -> Colorado.xlsx
F8: Connecticut | G8: CT | H8: =F8&".xlsx" -> Connecticut.xlsx
A9: Notes: | F9: Delaware | G9: DE | H9: =F9&".xlsx" -> Delaware.xlsx
A10: This variable is used to specify the percentage of potential electricity output from each | F10: Florida | G10: FL | H10: =F10&".xlsx" -> Florida.xlsx
A11: source that is guaranteed (e.g. dispatched before any least-cost dispatching | F11: Georgia | G11: GA | H11: =F11&".xlsx" -> Georgia.xlsx
A12: begins) in the BAU case. | F12: Hawaii | G12: HI | H12: =F12&".xlsx" -> Hawaii.xlsx
F13: Idaho | G13: ID | H13: =F13&".xlsx" -> Idaho.xlsx
A14: For nuclear plants, we guarantee full dispatch, as regulators and utilities often run | F14: Illinois | G14: IL | H14: =F14&".xlsx" -> Illinois.xlsx
A15: these plants as baseload irresective of cost, rather than ramping them up and down. | F15: Indiana | G15: IN | H15: =F15&".xlsx" -> Indiana.xlsx
F16: Iowa | G16: IA | H16: =F16&".xlsx" -> Iowa.xlsx
A17: For petroleum, we use the weighted average expected capacity factor. | F17: Kansas | G17: KS | H17: =F17&".xlsx" -> Kansas.xlsx
A18: In reality, petroleum is primarily used in fuel-switching applications in New England | F18: Kentucky | G18: KY | H18: =F18&".xlsx" -> Kentucky.xlsx
A19: (where there can be specific, unusual hours of NG shortage due to pipeline congestion) | F19: Louisiana | G19: LA | H19: =F19&".xlsx" -> Louisiana.xlsx
A20: and in places like Hawaii, without much NG access, where it is easier to transport petroleum | F20: Maine | G20: ME | H20: =F20&".xlsx" -> Maine.xlsx
A21: by ship due to its higher volumetric energy density. | F21: Maryland | G21: MD | H21: =F21&".xlsx" -> Maryland.xlsx
A22: We can't capture some of these unusual hours and sub-regional dynamics directly, so | F22: Massachusetts | G22: MA | H22: =F22&".xlsx" -> Massachusetts.xlsx
A23: we use guaranteed dispatch to align modeled petroleum dispatch with real-world experience. | F23: Michigan | G23: MI | H23: =F23&".xlsx" -> Michigan.xlsx
F24: Minnesota | G24: MN | H24: =F24&".xlsx" -> Minnesota.xlsx
F25: Mississippi | G25: MS | H25: =F25&".xlsx" -> Mississippi.xlsx
F26: Missouri | G26: MO | H26: =F26&".xlsx" -> Missouri.xlsx
F27: Montana | G27: MT | H27: =F27&".xlsx" -> Montana.xlsx
F28: Nebraska | G28: NE | H28: =F28&".xlsx" -> Nebraska.xlsx
F29: Nevada | G29: NV | H29: =F29&".xlsx" -> Nevada.xlsx
F30: New Hampshire | G30: NH | H30: =F30&".xlsx" -> New Hampshire.xlsx
F31: New Jersey | G31: NJ | H31: =F31&".xlsx" -> New Jersey.xlsx
F32: New Mexico | G32: NM | H32: =F32&".xlsx" -> New Mexico.xlsx
F33: New York | G33: NY | H33: =F33&".xlsx" -> New York.xlsx
F34: North Carolina | G34: NC | H34: =F34&".xlsx" -> North Carolina.xlsx
F35: North Dakota | G35: ND | H35: =F35&".xlsx" -> North Dakota.xlsx
... F51: Wyoming | G51: WY | H51: =F51&".xlsx" -> Wyoming.xlsx
A54: State
B55: Tot production | C55: Cap factor | D55: Percent of total
A56: RICE | B56: 5172 | C56: 18.2 | D56: 0.012260021
A57: Steam turbine | B57: 74000 | C57: 12.5 | D57: 0.17541406
...

Sheet petroleum adj
B1: estimated CF in sy
A2: AK | B2: 0
A3: AL | B3: 0.5254718
A4: AR | B4: 1
A5: AZ | B5: 0.69511174
A6: CA | B6: 0.28990572
A7: CO | B7: 0.011407292
A8: CT | B8: 0.058105706
A9: DC | B9: 0
A10: DE | B10: 0.31365652
A11: FL | B11: 0.83009344
A12: GA | B12: 0.067934573
A13: HI | B13: 0
... A52: WY | B52: 1

Sheet coal and gas factors
B2: hard coal | C2: natural gas combined cycle cf
A3: AL | B3: 0 | C3: 1
A4: AR | B4: 0.5 | C4: 0.78
A5: AZ | B5: 0 | C5: 1
A6: CA | B6: 0 | C6: 1
A7: CO | B7: 0.7 | C7: 1
A8: CT | B8: 0 | C8: 1
A9: DE | B9: 0.2 | C9: 0
A10: FL | B10: 0 | C10: 1
A11: GA | B11: 0 | C11: 1
A12: IA | B12: 0 | C12: 1
A13: ID | B13: 0 | C13: 0
A14: IL | B14: 0 | C14: 1
... A50: WY | B50: 0 | C50: 0.7

Sheet start year state specific CF
A1: State | B1: State | C1: hard coal | D1: natural gas steam turbine | E1: natural gas combined cycle cf | F1: natural gas peaker | G1: nuclear | H1: hydro | I1: petroleum | J1: crude oil
A2: Alabama | B2: AL | C2: =SUMIFS('coal and gas factors'!B:B,'coal and gas factors'!A:A,'start year state specific CF'!B2) -> 0 | D2: 1 | E2: =SUMIFS('coal and gas factors'!C:C,'coal and gas factors'!A:A,'start year state specific CF'!B2) -> 1 | F2: 1 | G2: 1 | H2: 0.9 | I2: =INDEX('petroleum adj'!B:B,MATCH(B2,'petroleum adj'!$A:$A,0)) -> 0.5254718 | J2: 1
A3: Alaska | B3: AK | C3: =SUMIFS('coal and gas factors'!B:B,'coal and gas factors'!A:A,'start year state specific CF'!B3) -> 0 | D3: 1 | E3: =SUMIFS('coal and gas factors'!C:C,'coal and gas factors'!A:A,'start year state specific CF'!B3) -> 0 | F3: 1 | G3: 1 | H3: 0.9 | I3: =INDEX('petroleum adj'!B:B,MATCH(B3,'petroleum adj'!$A:$A,0)) -> 0 | J3: 1
A4: Arizona | B4: AZ | C4: =SUMIFS('coal and gas factors'!B:B,'coal and gas factors'!A:A,'start year state specific CF'!B4) -> 0 | D4: 1 | E4: =SUMIFS('coal and gas factors'!C:C,'coal and gas factors'!A:A,'start year state specific CF'!B4) -> 1 | F4: 1 | G4: 1 | H4: 0.9 | I4: =INDEX('petroleum adj'!B:B,MATCH(B4,'petroleum adj'!$A:$A,0)) -> 0.69511174 | J4: 1
A5: Arkansas | B5: AR | C5: =SUMIFS('coal and gas factors'!B:B,'coal and gas factors'!A:A,'start year state specific CF'!B5) -> 0.5 | D5: 1 | E5: =SUMIFS('coal and gas factors'!C:C,'coal and gas factors'!A:A,'start year state specific CF'!B5) -> 0.78 | F5: 1 | G5: 1 | H5: 0.9 | I5: =INDEX('petroleum adj'!B:B,MATCH(B5,'petroleum adj'!$A:$A,0)) -> 1 | J5: 1
A6: California | B6: CA | C6: =SUMIFS('coal and gas factors'!B:B,'coal and gas factors'!A:A,'start year state specific CF'!B6) -> 0 | D6: 1 | E6: =SUMIFS('coal and gas factors'!C:C,'coal and gas factors'!A:A,'start year state specific CF'!B6) -> 1 | F6: 1 | G6: 1 | H6: 0.9 | I6: =INDEX('petroleum adj'!B:B,MATCH(B6,'petroleum adj'!$A:$A,0)) -> 0.28990572 | J6: 1
A7: Colorado | B7: CO | C7: =SUMIFS('coal and gas factors'!B:B,'coal and gas factors'!A:A,'start year state specific CF'!B7) -> 0.7 | D7: 1 | E7: =SUMIFS('coal and gas factors'!C:C,'coal and gas factors'!A:A,'start year state specific CF'!B7) -> 1 | F7: 1 | G7: 1 | H7: 0.9 | I7: =INDEX('petroleum adj'!B:B,MATCH(B7,'petroleum adj'!$A:$A,0)) -> 0.011407292 | J7: 1
A8: Connecticut | B8: CT | C8: =SUMIFS('coal and gas factors'!B:B,'coal and gas factors'!A:A,'start year state specific CF'!B8) -> 0 | D8: 1 | E8: =SUMIFS('coal and gas factors'!C:C,'coal and gas factors'!A:A,'start year state specific CF'!B8) -> 1 | F8: 1 | G8: 1 | H8: 0.9 | I8: =INDEX('petroleum adj'!B:B,MATCH(B8,'petroleum adj'!$A:$A,0)) -> 0.058105706 | J8: 1
A9: Delaware | B9: DE | C9: =SUMIFS('coal and gas factors'!B:B,'coal and gas factors'!A:A,'start year state specific CF'!B9) -> 0.2 | D9: 1 | E9: =SUMIFS('coal and gas factors'!C:C,'coal and gas factors'!A:A,'start year state specific CF'!B9) -> 0 | F9: 1 | G9: 1 | H9: 0.9 | I9: =INDEX('petroleum adj'!B:B,MATCH(B9,'petroleum adj'!$A:$A,0)) -> 0.31365652 | J9: 1
A10: Florida | B10: FL | C10: =SUMIFS('coal and gas factors'!B:B,'coal and gas factors'!A:A,'start year state specific CF'!B10) -> 0 | D10: 1 | E10: =SUMIFS('coal and gas factors'!C:C,'coal and gas factors'!A:A,'start year state specific CF'!B10) -> 1 | F10: 1 | G10: 1 | H10: 0.9 | I10: =INDEX('petroleum adj'!B:B,MATCH(B10,'petroleum adj'!$A:$A,0)) -> 0.83009344 | J10: 1
A11: Georgia | B11: GA | C11: =SUMIFS('coal and gas factors'!B:B,'coal and gas factors'!A:A,'start year state specific CF'!B11) -> 0 | D11: 1 | E11: =SUMIFS('coal and gas factors'!C:C,'coal and gas factors'!A:A,'start year state specific CF'!B11) -> 1 | F11: 1 | G11: 1 | H11: 0.9 | I11: =INDEX('petroleum adj'!B:B,MATCH(B11,'petroleum adj'!$A:$A,0)) -> 0.067934573 | J11: 1
A12: Hawaii | B12: HI | C12: =SUMIFS('coal and gas factors'!B:B,'coal and gas factors'!A:A,'start year state specific CF'!B12) -> 0 | D12: 1 | E12: =SUMIFS('coal and gas factors'!C:C,'coal and gas factors'!A:A,'start year state specific CF'!B12) -> 0 | F12: 1 | G12: 1 | H12: 0.9 | I12: =INDEX('petroleum adj'!B:B,MATCH(B12,'petroleum adj'!$A:$A,0)) -> 0 | J12: 1
A13: Idaho | B13: ID | C13: =SUMIFS('coal and gas factors'!B:B,'coal and gas factors'!A:A,'start year state specific CF'!B13) -> 0 | D13: 1 | E13: =SUMIFS('coal and gas factors'!C:C,'coal and gas factors'!A:A,'start year state specific CF'!B13) -> 0 | F13: 1 | G13: 1 | H13: 1 | I13: =INDEX('petroleum adj'!B:B,MATCH(B13,'petroleum adj'!$A:$A,0)) -> 0.027544707 | J13: 1
... A51: Wyoming | B51: WY | C51: =SUMIFS('coal and gas factors'!B:B,'coal and gas factors'!A:A,'start year state specific CF'!B51) -> 0 | D51: 1 | E51: =SUMIFS('coal and gas factors'!C:C,'coal and gas factors'!A:A,'start year state specific CF'!B51) -> 0.7 | F51: 1 | G51: 1 | H51: 0.9 | I51: =INDEX('petroleum adj'!B:B,MATCH(B51,'petroleum adj'!$A:$A,0)) -> 1 | J51: 1

Sheet EIA data
A1: Table 15. Capacity and usage factors, 2008 through 2023 | B1: Unnamed: 1 | C1: Unnamed: 2 | D1: Unnamed: 3 | E1: Unnamed: 4 | F1: Unnamed: 5 | G1: Unnamed: 6 | H1: Unnamed: 7 | I1: Unnamed: 8 | J1: Unnamed: 9 | K1: Unnamed: 10 | L1: Unnamed: 11 | M1: Unnamed: 12 | N1: Unnamed: 13 | O1: Unnamed: 14 | P1: Unnamed: 15 | Q1: Unnamed: 16 | R1: Unnamed: 17 | S1: a
A2: Alabama | S2: Alabama
A3: Generation technology | B3: 2023 Time adjusted capacity (MW) | C3: Year 2023 | D3: Year 2022 | E3: Year 2021 | F3: Year 2020 | G3: Year 2019 | H3: Year 2018 | I3: Year 2017 | J3: Year 2016 | K3: Year 2015 | L3: Year 2014 | M3: Year 2013 | N3: Year 2012 | O3: Year 2011 | P3: Year 2010 | Q3: Year 2009 | R3: Year 2008 | S3: Alabama
A4: Capacity Factors | S4: Alabama
A5: Nuclear | B5: 5452.7 | C5: 95.4 | D5: 88.6 | E5: 96.4 | F5: 89.4 | G5: 90.8 | H5: 87.7 | I5: 96.2 | J5: 89.8 | K5: 94.5 | L5: 92.9 | M5: 92.4 | N5: 92.2 | O5: 89.1 | P5: 85.9 | Q5: 90.9 | R5: 89.1 | S5: Alabama
A6: Other, Biomass | B6: 6.4 | C6: 73.8 | D6: 76.5 | E6: 78.4 | F6: 66.4 | G6: 72.2 | H6: 67.2 | I6: 73.8 | J6: 67.8 | K6: 77.8 | L6: 79.5 | M6: 84.6 | N6: 0 | S6: Alabama
A7: Wood | B7: 617.1 | C7: 67.6 | D7: 68.2 | E7: 72.7 | F7: 71.4 | G7: 67.4 | H7: 73 | I7: 66.6 | J7: 67.1 | K7: 66.5 | L7: 53.5 | M7: 52.7 | N7: 57.3 | O7: 58.9 | P7: 59.2 | Q7: 71 | R7: 61.3 | S7: Alabama
A8: Natural Gas - CC | B8: 10052.6 | C8: 63.7 | D8: 64.8 | E8: 58.2 | F8: 59.1 | G8: 58.3 | H8: 61.1 | I8: 58 | J8: 65.8 | K8: 65.4 | L8: 57.1 | M8: 55.2 | N8: 63.5 | O8: 54.7 | P8: 46.7 | Q8: 39.3 | R8: 28.3 | S8: Alabama
A9: Coal | B9: 4728 | C9: 47.9 | D9: 66.3 | E9: 67.2 | F9: 49.4 | G9: 56.2 | H9: 57.8 | I9: 58.8 | J9: 59.2 | K9: 49.6 | L9: 50.6 | M9: 48.6 | N9: 48.1 | O9: 57.2 | P9: 63.2 | Q9: 55.6 | R9: 74.1 | S9: Alabama
A10: Hydroelectric | B10: 3291.8 | C10: 29.2 | D10: 35.3 | E10: 40 | F10: 46.2 | G10: 39.6 | H10: 38.6 | I10: 32 | J10: 26.1 | K10: 34.4 | L10: 33 | M10: 45 | N10: 25.8 | O10: 31 | P10: 30.3 | Q10: 43.7 | R10: 21.3 | S10: Alabama
A11: Solar - PV | B11: 558.6 | C11: 23.6 | D11: 24.3 | E11: 20.4 | F11: 21.6 | G11: 22.6 | H11: 22.7 | I11: 22.9 | J11: 18.6 | S11: Alabama
A12: Natural Gas - ST | B12: 1769.1 | C12: 22.3 | D12: 16.5 | E12: 10.8 | F12: 15.5 | G12: 29 | H12: 31.5 | I12: 26.5 | J12: 12.2 | K12: 11.8 | L12: 60.6 | M12: 69 | N12: 88.5 | O12: 82.6 | P12: 75.5 | Q12: 76 | R12: 79.6 | S12: Alabama
A13: Natural Gas - GT | B13: 2922.7 | C13: 5.9 | D13: 8.9 | E13: 5.5 | F13: 4.6 | G13: 6.9 | H13: 4.5 | I13: 2.8 | J13: 4.1 | K13: 3.1 | L13: 2.2 | M13: 1.3 | N13: 3.5 | O13: 3.3 | P13: 2.9 | Q13: 2.3 | R13: 2.4 | S13: Alabama
A14: Petroleum - IC | B14: 26.6 | C14: 0.2 | D14: 0.2 | E14: 0.2 | F14: 0.4 | G14: 0.4 | H14: 0.3 | I14: 0.2 | J14: 0.3 | K14: 0.4 | L14: 0.3 | M14: 0.3 | N14: 0.3 | O14: 0.3 | P14: 0.5 | Q14: 0.3 | R14: 0.3 | S14: Alabama
A15: Petroleum - GT | B15: 16 | C15: 0.1 | D15: 0.2 | E15: 0.1 | F15: 0.1 | G15: 0.1 | H15: 0.1 | I15: 0.1 | J15: 0.1 | K15: 0.2 | L15: 0.1 | M15: 0.1 | N15: 0.1 | O15: 0.1 | P15: 0.5 | Q15: 0.5 | R15: 0.5 | S15: Alabama
A16: Natural Gas - OTH | B16: 110 | C16: 0 | D16: 0 | E16: 0 | F16: 0 | G16: 0 | H16: 0 | I16: 0 | J16: 0 | K16: 0 | L16: 0.3 | M16: 0 | S16: Alabama
A17: Other, Gas | D17: 0.3 | E17: 0.3 | F17: 0.3 | G17: 1.7 | H17: 3 | I17: 5.7 | J17: 15.4 | K17: 5.4 | L17: 26.2 | M17: 39.6 | N17: 24.1 | O17: 42.7 | P17: 41.2 | Q17: 23 | R17: 32.8 | S17: Alabama
A18: Usage Factors | S18: Alabama
A19: Battery | B19: 1 | C19: 5.8 | D19: 3.2 | E19: 1.9 | F19: 3 | G19: 3.9 | H19: 3.5 | S19: Alabama
A20: All Sources | B20: 29552.6 | S20: Alabama
A21: Note: Time adjusted capacity for the year is the capacity of all the generators that were included in the capacity factor calculation. Sources: U.S. Energy Information Administration, Form EIA-860, Annual Electric Generator Report. and U.S. Energy Information Administration, Form EIA-923, Power Plant Operations Report | S21: Alabama
A22: Alaska | S22: Alaska
A23: Generation technology | B23: 2023 Time adjusted capacity (MW) | C23: Year 2023 | D23: Year 2022 | E23: Year 2021 | F23: Year 2020 | G23: Year 2019 | H23: Year 2018 | I23: Year 2017 | J23: Year 2016 | K23: Year 2015 | L23: Year 2014 | M23: Year 2013 | N23: Year 2012 | O23: Year 2011 | P23: Year 2010 | Q23: Year 2009 | R23: Year 2008 | S23: Alaska
A24: Capacity Factors | S24: Alaska
A25: Natural Gas - CC | B25: 374.6 | C25: 65.4 | D25: 73.7 | E25: 66.9 | F25: 40 | G25: 39.8 | H25: 49.2 | I25: 51 | J25: 49.2 | K25: 49.3 | L25: 52.9 | M25: 54.3 | N25: 76.2 | O25: 87.2 | P25: 83.4 | Q25: 80.9 | R25: 80.9 | S25: Alaska
A26: Other, Biomass | B26: 7 | C26: 63.5 | D26: 66.6 | E26: 62.1 | F26: 63.4 | G26: 60.2 | H26: 70 | I26: 71.8 | J26: 69.1 | K26: 81.8 | L26: 91.6 | M26: 84.1 | N26: 0 | S26: Alaska
A27: Coal | B27: 167.9 | C27: 50.3 | D27: 50.1 | E27: 51.6 | F27: 49.7 | G27: 52.6 | H27: 48.2 | I27: 48 | J27: 46.4 | K27: 68 | L27: 62.3 | M27: 67.1 | N27: 73.2 | O27: 68.5 | P27: 64.8 | Q27: 65.8 | R27: 52.7 | S27: Alaska
A28: Natural Gas - IC | B28: 174.4 | C28: 47.2 | D28: 34.5 | E28: 43.9 | F28: 47 | G28: 47.4 | H28: 40.3 | I28: 49.1 | J28: 53.5 | K28: 34.8 | L28: 14.2 | M28: 11.4 | N28: 30.4 | O28: 5.3 | P28: 3.3 | Q28: 3.3 | R28: 2.6 | S28: Alaska
A29: Hydroelectric | B29: 475.1 | C29: 42.7 | D29: 41.1 | E29: 40.6 | F29: 42.7 | G29: 39.4 | H29: 40.4 | I29: 39.9 | J29: 40.6 | K29: 40.6 | L29: 40.7 | M29: 39.4 | N29: 43.1 | O29: 37 | P29: 39.5 | Q29: 37.3 | R29: 33.6 | S29: Alaska
A30: Wind - Onshore | B30: 59 | C30: 21.6 | D30: 27 | E30: 25.4 | F30: 24.3 | G30: 26.7 | H30: 29.2 | I30: 26.7 | S30: Alaska
A31: Petroleum - IC | B31: 460.5 | C31: 10 | D31: 9.8 | E31: 10 | F31: 9.8 | G31: 11 | H31: 10.7 | I31: 10.6 | J31: 10 | K31: 9.9 | L31: 10.4 | M31: 11.5 | N31: 9.6 | O31: 10.2 | P31: 9 | Q31: 11 | R31: 11.1 | S31: Alaska
A32: Petroleum - GT | B32: 237 | C32: 5.7 | D32: 4.7 | E32: 6 | F32: 9.5 | G32: 5.3 | H32: 5.4 | I32: 7 | J32: 6.6 | K32: 4.2 | L32: 3.6 | M32: 2.8 | N32: 10.8 | O32: 6.4 | P32: 29.3 | Q32: 32.1 | R32: 24.5 | S32: Alaska
A33: Natural Gas - GT | B33: 712.6 | C33: 4.4 | D33: 3.9 | E33: 3.2 | F33: 4.3 | G33: 5.4 | H33: 4.8 | I33: 6.6 | J33: 6.8 | K33: 10.9 | L33: 11.7 | M33: 15 | N33: 31 | O33: 31.2 | P33: 30.3 | Q33: 27.9 | R33: 37.4 | S33: Alaska
A34: Other, not Biomass or Gas | B34: 2.9 | C34: 2 | D34: 1.5 | E34: 0 | F34: 0 | G34: 0 | H34: 0 | I34: 0 | J34: 0 | L34: 37 | S34: Alaska
A35: Solar - PV | B35: 2.7 | C35: 0.2 | D35: 0 | E35: 0 | S35: Alaska
A36: Wind | J36: 31.8 | K36: 30.1 | L36: 28.9 | M36: 28.7 | N36: 20.1 | O36: 19.2 | P36: 19.4 | Q36: 13.8 | R36: 0.1 | S36: Alaska
A37: Usage Factors | S37: Alaska
A38: Battery | B38: 91.7 | C38: 0.4 | D38: 0.1 | E38: 0.1 | F38: 0.1 | G38: 0.1 | H38: 0.1 | I38: 0.1 | J38: 0.1 | K38: 0.2 | L38: 0.2 | M38: 0.3 | S38: Alaska
A39: All Sources | B39: 2816.4 | S39: Alaska
A40: Note: Time adjusted capacity for the year is the capacity of all the generators that were included in the capacity factor calculation. Sources: U.S. Energy Information Administration, Form EIA-860, Annual Electric Generator Report. and U.S. Energy Information Administration, Form EIA-923, Power Plant Operations Report | S40: Alaska
...

Sheet shelf
A1: Winter | B1: 120
A2: Spring | B2: 92
A3: Summer | B3: 92
A4: Fall | B4: 61
A5: Summer Peak | B5: 0
A6: Winter Peak | B6: 0

Sheet all_csv_SYSHECF-hard-coal
A1: Hour0 | B1: Hour1 | C1: Hour2 | D1: Hour3 | E1: Hour4 | F1: Hour5 | G1: Hour6 | H1: Hour7 | I1: Hour8 | J1: Hour9 | K1: Hour10 | L1: Hour11 | M1: Hour12 | N1: Hour13 | O1: Hour14 | P1: Hour15 | Q1: Hour16 | R1: Hour17 | S1: Hour18 | T1: Hour19 | U1: Hour20 | V1: Hour21 | W1: Hour22 | X1: Hour23 | Y1: State | Z1: Metric Name | AA1: hard coal | AB1: SHELF | AC1: total
A2: 0.61413745 | B2: 0.60809257 | C2: 0.61473514 | D2: 0.64102882 | E2: 0.6987199 | F2: 0.74802809 | G2: 0.74479974 | H2: 0.70597652 | I2: 0.67740107 | J2: 0.67274126 | K2: 0.67117841 | L2: 0.65798494 | M2: 0.63342093 | N2: 0.61974717 | O2: 0.65035845 | P2: 0.74554963 | Q2: 0.79462078 | R2: 0.79598774 | S2: 0.79598774 | T2: 0.79516747 | U2: 0.7840945 | V2: 0.7320195 | W2: 0.67114187 | X2: 0.63433208 | Y2: AL | Z2: SYSHECF-hard-coal | AA2: Winter | AB2: =INDEX(shelf!$B$1:$B$6,MATCH(AA2,shelf!$A$1:$A$6,0)) -> 120 | AC2: {=SUMPRODUCT(A2:X2*AB2)} -> 2004.8702
A3: 0.34608895 | B3: 0.34107008 | C3: 0.34427857 | D3: 0.37258099 | E3: 0.44597596 | F3: 0.45682853 | G3: 0.41825205 | H3: 0.41149508 | I3: 0.43242093 | J3: 0.48071561 | K3: 0.53211035 | L3: 0.56833766 | M3: 0.5900285 | N3: 0.61291328 | O3: 0.6400293 | P3: 0.69081971 | Q3: 0.74583303 | R3: 0.75071546 | S3: 0.75607432 | T3: 0.75545868 | U3: 0.74497907 | V3: 0.65557424 | W3: 0.50396501 | X3: 0.37364883 | Y3: AL | Z3: SYSHECF-hard-coal | AA3: Spring | AB3: =INDEX(shelf!$B$1:$B$6,MATCH(AA3,shelf!$A$1:$A$6,0)) -> 92 | AC3: {=SUMPRODUCT(A3:X3*AB3)} -> 1193.2579
A4: 0.57797553 | B4: 0.55803953 | C4: 0.53380089 | D4: 0.54448628 | E4: 0.5608803 | F4: 0.54201365 | G4: 0.56641777 | H4: 0.64645014 | I4: 0.70674117 | J4: 0.75476 | K4: 0.78960927 | L4: 0.80606377 | M4: 0.81608112 | N4: 0.81991229 | O4: 0.82316719 | P4: 0.82601238 | Q4: 0.82656175 | R4: 0.82770294 | S4: 0.82992544 | T4: 0.8269803 | U4: 0.82183512 | V4: 0.79483047 | W4: 0.73439747 | X4: 0.63172064 | Y4: AL | Z4: SYSHECF-hard-coal | AA4: Summer | AB4: =INDEX(shelf!$B$1:$B$6,MATCH(AA4,shelf!$A$1:$A$6,0)) -> 92 | AC4: {=SUMPRODUCT(A4:X4*AB4)} -> 1579.3056
A5: 0.38687286 | B5: 0.37616117 | C5: 0.37220962 | D5: 0.38751593 | E5: 0.5356097 | F5: 0.56928251 | G5: 0.5219178 | H5: 0.51220171 | I5: 0.56553403 | J5: 0.61929945 | K5: 0.66105806 | L5: 0.68915622 | M5: 0.70063408 | N5: 0.70948067 | O5: 0.73250288 | P5: 0.77560753 | Q5: 0.80005306 | R5: 0.80206612 | S5: 0.80025194 | T5: 0.79883222 | U5: 0.74123565 | V5: 0.67256587 | W5: 0.5438923 | X5: 0.42211544 | Y5: AL | Z5: SYSHECF-hard-coal | AA5: Fall | AB5: =INDEX(shelf!$B$1:$B$6,MATCH(AA5,shelf!$A$1:$A$6,0)) -> 61 | AC5: {=SUMPRODUCT(A5:X5*AB5)} -> 896.45947
A6: 0.34262944 | B6: 0.34262944 | C6: 0.34262944 | D6: 0.34262944 | E6: 0.34262944 | F6: 0.34262944 | G6: 0.34262944 | H6: 0.58913701 | I6: 0.65626337 | J6: 0.8244264 | K6: 0.8244264 | L6: 0.8244264 | M6: 0.84501742 | N6: 0.84501742 | O6: 0.84501742 | P6: 0.84501742 | Q6: 0.84501742 | R6: 0.8244264 | S6: 0.85656447 | T6: 0.85079094 | U6: 0.84501742 | V6: 0.8244264 | W6: 0.8244264 | X6: 0.73946789 | Y6: AL | Z6: SYSHECF-hard-coal | AA6: Summer Peak | AB6: =INDEX(shelf!$B$1:$B$6,MATCH(AA6,shelf!$A$1:$A$6,0)) -> 0 | AC6: {=SUMPRODUCT(A6:X6*AB6)} -> 0
A7: 0.70870012 | B7: 0.70870012 | C7: 0.70870012 | D7: 0.8030132 | E7: 0.8030132 | F7: 0.8030132 | G7: 0.8030132 | H7: 0.8030132 | I7: 0.70870012 | J7: 0.63485017 | K7: 0.63485017 | L7: 0.63485017 | M7: 0.63485017 | N7: 0.63485017 | O7: 0.63485017 | P7: 0.70870012 | Q7: 0.8030132 | R7: 0.8030132 | S7: 0.8030132 | T7: 0.8030132 | U7: 0.8030132 | V7: 0.8030132 | W7: 0.70870012 | X7: 0.70870012 | Y7: AL | Z7: SYSHECF-hard-coal | AA7: Winter Peak | AB7: =INDEX(shelf!$B$1:$B$6,MATCH(AA7,shelf!$A$1:$A$6,0)) -> 0 | AC7: {=SUMPRODUCT(A7:X7*AB7)} -> 0
A8: 0.26978691 | B8: 0.26368842 | C8: 0.26533671 | D8: 0.28444208 | E8: 0.34911989 | F8: 0.41250344 | G8: 0.4239309 | H8: 0.38696883 | I8: 0.36144521 | J8: 0.35889583 | K8: 0.36300362 | L8: 0.34472498 | M8: 0.31699955 | N8: 0.29689577 | O8: 0.31781885 | P8: 0.41861518 | Q8: 0.46292828 | R8: 0.48052406 | S8: 0.47136696 | T8: 0.46509194 | U8: 0.4581331 | V8: 0.42755242 | W8: 0.34843994 | X8: 0.29312778 | Y8: AR | Z8: SYSHECF-hard-coal | AA8: Winter | AB8: =INDEX(shelf!$B$1:$B$6,MATCH(AA8,shelf!$A$1:$A$6,0)) -> 120 | AC8: {=SUMPRODUCT(A8:X8*AB8)} -> 1060.9609
A9: 0.18893068 | B9: 0.18860089 | C9: 0.18897918 | D9: 0.18910648 | E9: 0.20186029 | F9: 0.23024021 | G9: 0.22055068 | H9: 0.1989791 | I9: 0.20143916 | J9: 0.21573117 | K9: 0.23908466 | L9: 0.26205016 | M9: 0.28373813 | N9: 0.29918157 | O9: 0.31634143 | P9: 0.37033525 | Q9: 0.41522677 | R9: 0.4334641 | S9: 0.42537097 | T9: 0.41946309 | U9: 0.41419982 | V9: 0.33103557 | W9: 0.20693522 | X9: 0.19129739 | Y9: AR | Z9: SYSHECF-hard-coal | AA9: Spring | AB9: =INDEX(shelf!$B$1:$B$6,MATCH(AA9,shelf!$A$1:$A$6,0)) -> 92 | AC9: {=SUMPRODUCT(A9:X9*AB9)} -> 610.15706
A10: 0.5783273 | B10: 0.54901683 | C10: 0.53878453 | D10: 0.54120136 | E10: 0.56155526 | F10: 0.5753972 | G10: 0.58886774 | H10: 0.64354654 | I10: 0.71231431 | J10: 0.82678678 | K10: 0.93708249 | L10: 1 | M10: 1 | N10: 1 | O10: 1 | P10: 1 | Q10: 1 | R10: 1 | S10: 1 | T10: 1 | U10: 1 | V10: 0.88861435 | W10: 0.72323169 | X10: 0.64645272 | Y10: AR | Z10: SYSHECF-hard-coal | AA10: Summer | AB10: =INDEX(shelf!$B$1:$B$6,MATCH(AA10,shelf!$A$1:$A$6,0)) -> 92 | AC10: {=SUMPRODUCT(A10:X10*AB10)} -> 1776.6285
A11: 0.22921258 | B11: 0.22822817 | C11: 0.22822817 | D11: 0.23019698 | E11: 0.23907981 | F11: 0.27629526 | G11: 0.27065092 | H11: 0.25757873 | I11: 0.27202117 | J11: 0.31861317 | K11: 0.34736638 | L11: 0.37818959 | M11: 0.42195029 | N11: 0.43885405 | O11: 0.46061279 | P11: 0.52533312 | Q11: 0.53689243 | R11: 0.54399113 | S11: 0.54119639 | T11: 0.52301016 | U11: 0.4772069 | V11: 0.34660141 | W11: 0.25912269 | X11: 0.22716208 | Y11: AR | Z11: SYSHECF-hard-coal | AA11: Fall | AB11: =INDEX(shelf!$B$1:$B$6,MATCH(AA11,shelf!$A$1:$A$6,0)) -> 61 | AC11: {=SUMPRODUCT(A11:X11*AB11)} -> 523.23326
A12: 0.67752912 | B12: 0.6174803 | C12: 0.6174803 | D12: 0.6174803 | E12: 0.6174803 | F12: 0.6174803 | G12: 0.6174803 | H12: 0.85767557 | I12: 0.9469122 | J12: 0.9469122 | K12: 1 | L12: 1 | M12: 1 | N12: 1 | O12: 1 | P12: 1 | Q12: 1 | R12: 1 | S12: 1 | T12: 1 | U12: 1 | V12: 0.9469122 | W12: 0.90749935 | X12: 0.85767557 | Y12: AR | Z12: SYSHECF-hard-coal | AA12: Summer Peak | AB12: =INDEX(shelf!$B$1:$B$6,MATCH(AA12,shelf!$A$1:$A$6,0)) -> 0 | AC12: {=SUMPRODUCT(A12:X12*AB12)} -> 0
A13: 0.21963366 | B13: 0.21963366 | C13: 0.21963366 | D13: 0.21963366 | E13: 0.45982892 | F13: 0.45982892 | G13: 0.54906555 | H13: 0.54906555 | I13: 0.45982892 | J13: 0.45982892 | K13: 0.45982892 | L13: 0.45982892 | M13: 0.27968247 | N13: 0.21963366 | O13: 0.21963366 | P13: 0.45982892 | Q13: 0.54906555 | R13: 0.54906555 | S13: 0.45982892 | T13: 0.40037502 | U13: 0.40037502 | V13: 0.40037502 | W13: 0.34806004 | X13: 0.22019139 | Y13: AR | Z13: SYSHECF-hard-coal | AA13: Winter Peak | AB13: =INDEX(shelf!$B$1:$B$6,MATCH(AA13,shelf!$A$1:$A$6,0)) -> 0 | AC13: {=SUMPRODUCT(A13:X13*AB13)} -> 0
... A289: 0.76130518 | B289: 0.76130518 | C289: 0.76130518 | D289: 0.76130518 | E289: 0.76130518 | F289: 0.76130518 | G289: 0.76219513 | H289: 0.76130518 | I289: 0.71230833 | J289: 0.71230833 | K289: 0.71230833 | L289: 0.71230833 | M289: 0.71230833 | N289: 0.71230833 | O289: 0.52845068 | P289: 0.71230833 | Q289: 0.7878884 | R289: 0.7878884 | S289: 0.7878884 | T289: 0.7878884 | U289: 0.7878884 | V289: 0.7878884 | W289: 0.76130518 | X289: 0.76130518 | Y289: WY | Z289: SYSHECF-hard-coal | AA289: Winter Peak | AB289: =INDEX(shelf!$B$1:$B$6,MATCH(AA289,shelf!$A$1:$A$6,0)) -> 0 | AC289: {=SUMPRODUCT(A289:X289*AB289)} -> 0

Sheet CF coal 2023-2024
A1: State | B1: State | C1: SYSHECF | D1: EIA actual CF | E1: has coal? | F1: BGDPBES value
A2: Alabama | B2: AL | C2: =SUMIFS('all_csv_SYSHECF-hard-coal'!AC:AC,'all_csv_SYSHECF-hard-coal'!Y:Y,'CF coal 2023-2024'!B2)/8760 -> 0.6477047 | D2: =SUMIFS('EIA data'!C:C,'EIA data'!A:A,"coal",'EIA data'!S:S,'CF coal 2023-2024'!A2)/100 -> 0.479 | E2: Y | F2: =IF(E2="Y",MIN(IFERROR(D2/C2*0.95,0),1),0) -> 0.70255782
A3: Arizona | B3: AZ | C3: =SUMIFS('all_csv_SYSHECF-hard-coal'!AC:AC,'all_csv_SYSHECF-hard-coal'!Y:Y,'CF coal 2023-2024'!B3)/8760 -> 0.55217525 | D3: =SUMIFS('EIA data'!C:C,'EIA data'!A:A,"coal",'EIA data'!S:S,'CF coal 2023-2024'!A3)/100 -> 0.489 | E3: Y | F3: =IF(E3="Y",MIN(IFERROR(D3/C3*0.95,0),1),0) -> 0.84130898
A4: Arkansas | B4: AR | C4: =SUMIFS('all_csv_SYSHECF-hard-coal'!AC:AC,'all_csv_SYSHECF-hard-coal'!Y:Y,'CF coal 2023-2024'!B4)/8760 -> 0.45330818 | D4: =SUMIFS('EIA data'!C:C,'EIA data'!A:A,"coal",'EIA data'!S:S,'CF coal 2023-2024'!A4)/100 -> 0.407 | E4: Y | F4: =IF(E4="Y",MIN(IFERROR(D4/C4*0.95,0),1),0) -> 0.85295173
A5: California | B5: CA | C5: =SUMIFS('all_csv_SYSHECF-hard-coal'!AC:AC,'all_csv_SYSHECF-hard-coal'!Y:Y,'CF coal 2023-2024'!B5)/8760 -> 0.39723199 | D5: =SUMIFS('EIA data'!C:C,'EIA data'!A:A,"coal",'EIA data'!S:S,'CF coal 2023-2024'!A5)/100 -> 0.49 | E5: N | F5: =IF(E5="Y",MIN(IFERROR(D5/C5*0.95,0),1),0) -> 0
A6: Colorado | B6: CO | C6: =SUMIFS('all_csv_SYSHECF-hard-coal'!AC:AC,'all_csv_SYSHECF-hard-coal'!Y:Y,'CF coal 2023-2024'!B6)/8760 -> 0.64391099 | D6: =SUMIFS('EIA data'!C:C,'EIA data'!A:A,"coal",'EIA data'!S:S,'CF coal 2023-2024'!A6)/100 -> 0.569 | E6: Y | F6: =IF(E6="Y",MIN(IFERROR(D6/C6*0.95,0),1),0) -> 0.83947938
A7: Connecticut | B7: CT | C7: =SUMIFS('all_csv_SYSHECF-hard-coal'!AC:AC,'all_csv_SYSHECF-hard-coal'!Y:Y,'CF coal 2023-2024'!B7)/8760 -> 0.1191696 | D7: =SUMIFS('EIA data'!C:C,'EIA data'!A:A,"coal",'EIA data'!S:S,'CF coal 2023-2024'!A7)/100 -> 0 | E7: Y | F7: =IF(E7="Y",MIN(IFERROR(D7/C7*0.95,0),1),0) -> 0
A8: Delaware | B8: DE | C8: =SUMIFS('all_csv_SYSHECF-hard-coal'!AC:AC,'all_csv_SYSHECF-hard-coal'!Y:Y,'CF coal 2023-2024'!B8)/8760 -> 0.39723199 | D8: =SUMIFS('EIA data'!C:C,'EIA data'!A:A,"coal",'EIA data'!S:S,'CF coal 2023-2024'!A8)/100 -> 0.004 | E8: Y | F8: =IF(E8="Y",MIN(IFERROR(D8/C8*0.95,0),1),0) -> 0.0095661983
A9: Florida | B9: FL | C9: =SUMIFS('all_csv_SYSHECF-hard-coal'!AC:AC,'all_csv_SYSHECF-hard-coal'!Y:Y,'CF coal 2023-2024'!B9)/8760 -> 0.41607212 | D9: =SUMIFS('EIA data'!C:C,'EIA data'!A:A,"coal",'EIA data'!S:S,'CF coal 2023-2024'!A9)/100 -> 0.348 | E9: Y | F9: =IF(E9="Y",MIN(IFERROR(D9/C9*0.95,0),1),0) -> 0.79457378
A10: Georgia | B10: GA | C10: =SUMIFS('all_csv_SYSHECF-hard-coal'!AC:AC,'all_csv_SYSHECF-hard-coal'!Y:Y,'CF coal 2023-2024'!B10)/8760 -> 0.25033195 | D10: =SUMIFS('EIA data'!C:C,'EIA data'!A:A,"coal",'EIA data'!S:S,'CF coal 2023-2024'!A10)/100 -> 0.331 | E10: Y | F10: =IF(E10="Y",MIN(IFERROR(D10/C10*0.95,0),1),0) -> 1
A11: Idaho | B11: ID | C11: =SUMIFS('all_csv_SYSHECF-hard-coal'!AC:AC,'all_csv_SYSHECF-hard-coal'!Y:Y,'CF coal 2023-2024'!B11)/8760 -> 0.39723199 | D11: =SUMIFS('EIA data'!C:C,'EIA data'!A:A,"coal",'EIA data'!S:S,'CF coal 2023-2024'!A11)/100 -> 0 | E11: N | F11: =IF(E11="Y",MIN(IFERROR(D11/C11*0.95,0),1),0) -> 0
A12: Illinois | B12: IL | C12: =SUMIFS('all_csv_SYSHECF-hard-coal'!AC:AC,'all_csv_SYSHECF-hard-coal'!Y:Y,'CF coal 2023-2024'!B12)/8760 -> 0.51572611 | D12: =SUMIFS('EIA data'!C:C,'EIA data'!A:A,"coal",'EIA data'!S:S,'CF coal 2023-2024'!A12)/100 -> 0.454 | E12: Y | F12: =IF(E12="Y",MIN(IFERROR(D12/C12*0.95,0),1),0) -> 0.83629662
A13: Indiana | B13: IN | C13: =SUMIFS('all_csv_SYSHECF-hard-coal'!AC:AC,'all_csv_SYSHECF-hard-coal'!Y:Y,'CF coal 2023-2024'!B13)/8760 -> 0.43816897 | D13: =SUMIFS('EIA data'!C:C,'EIA data'!A:A,"coal",'EIA data'!S:S,'CF coal 2023-2024'!A13)/100 -> 0.361 | E13: Y | F13: =IF(E13="Y",MIN(IFERROR(D13/C13*0.95,0),1),0) -> 0.78268892
... A42: Texas | B42: TX | C42: =SUMIFS('all_csv_SYSHECF-hard-coal'!AC:AC,'all_csv_SYSHECF-hard-coal'!Y:Y,'CF coal 2023-2024'!B42)/8760 -> 0.5234029 | D42: =SUMIFS('EIA data'!C:C,'EIA data'!A:A,"coal",'EIA data'!S:S,'CF coal 2023-2024'!A42)/100 -> 0.493 | E42: Y | F42: =IF(E42="Y",MIN(IFERROR(D42/C42*0.95,0),1),0) -> 0.89481736
A43: Utah | B43: UT | C43: =SUMIFS('all_csv_SYSHECF-hard-coal'!AC:AC,'all_csv_SYSHECF-hard-coal'!Y:Y,'CF coal 2023-2024'!B43)/8760 -> 0.65578557 | D43: =SUMIFS('EIA data'!C:C,'EIA data'!A:A,"coal",'EIA data'!S:S,'CF coal 2023-2024'!A43)/100 -> 0.391 | E43: Y | F43: 0
A44: Vermont | B44: VT | C44: =SUMIFS('all_csv_SYSHECF-hard-coal'!AC:AC,'all_csv_SYSHECF-hard-coal'!Y:Y,'CF coal 2023-2024'!B44)/8760 -> 0.39723199 | D44: =SUMIFS('EIA data'!C:C,'EIA data'!A:A,"coal",'EIA data'!S:S,'CF coal 2023-2024'!A44)/100 -> 0 | E44: N | F44: =IF(E44="Y",MIN(IFERROR(D44/C44*0.95,0),1),0) -> 0
A45: Virginia | B45: VA | C45: =SUMIFS('all_csv_SYSHECF-hard-coal'!AC:AC,'all_csv_SYSHECF-hard-coal'!Y:Y,'CF coal 2023-2024'!B45)/8760 -> 0.12321155 | D45: =SUMIFS('EIA data'!C:C,'EIA data'!A:A,"coal",'EIA data'!S:S,'CF coal 2023-2024'!A45)/100 -> 0.099 | E45: Y | F45: =IF(E45="Y",MIN(IFERROR(D45/C45*0.95,0),1),0) -> 0.76332128
A46: Washington | B46: WA | C46: =SUMIFS('all_csv_SYSHECF-hard-coal'!AC:AC,'all_csv_SYSHECF-hard-coal'!Y:Y,'CF coal 2023-2024'!B46)/8760 -> 0.52773563 | D46: =SUMIFS('EIA data'!C:C,'EIA data'!A:A,"coal",'EIA data'!S:S,'CF coal 2023-2024'!A46)/100 -> 0.706 | E46: Y | F46: =IF(E46="Y",MIN(IFERROR(D46/C46*0.95,0),1),0) -> 1
A47: West Virginia | B47: WV | C47: =SUMIFS('all_csv_SYSHECF-hard-coal'!AC:AC,'all_csv_SYSHECF-hard-coal'!Y:Y,'CF coal 2023-2024'!B47)/8760 -> 0.40795376 | D47: =SUMIFS('EIA data'!C:C,'EIA data'!A:A,"coal",'EIA data'!S:S,'CF coal 2023-2024'!A47)/100 -> 0.41 | E47: Y | F47: =IF(E47="Y",MIN(IFERROR(D47/C47*0.95,0),1),0) -> 0.95476506
A48: Wisconsin | B48: WI | C48: =SUMIFS('all_csv_SYSHECF-hard-coal'!AC:AC,'all_csv_SYSHECF-hard-coal'!Y:Y,'CF coal 2023-2024'!B48)/8760 -> 0.58269108 | D48: =SUMIFS('EIA data'!C:C,'EIA data'!A:A,"coal",'EIA data'!S:S,'CF coal 2023-2024'!A48)/100 -> 0.462 | E48: Y | F48: =IF(E48="Y",MIN(IFERROR(D48/C48*0.95,0),1),0) -> 0.75322931
A49: Wyoming | B49: WY | C49: =SUMIFS('all_csv_SYSHECF-hard-coal'!AC:AC,'all_csv_SYSHECF-hard-coal'!Y:Y,'CF coal 2023-2024'!B49)/8760 -> 0.60255642 | D49: =SUMIFS('EIA data'!C:C,'EIA data'!A:A,"coal",'EIA data'!S:S,'CF coal 2023-2024'!A49)/100 -> 0.584 | E49: Y | F49: =IF(E49="Y",MIN(IFERROR(D49/C49*0.95,0),1),0) -> 0.92074365

Sheet CF nat gas 2023-2024
A1: natural gas cc | B1: 2023 | C1: 2024 | D1: 2025 | E1: 2026 | F1: 2027 | G1: 2028
A2: Alabama | B2: 0 | C2: 0 | D2: 0 | E2: 0 | F2: 0 | G2: 0
A3: Arizona | B3: 0 | C3: 0 | D3: 0 | E3: 0 | F3: 0 | G3: 0
A4: Arkansas | B4: 0 | C4: 0 | D4: 0 | E4: 0 | F4: 0 | G4: 0
A5: California | B5: 1 | C5: 1 | D5: 0 | E5: 0 | F5: 0 | G5: 0
A6: Colorado | B6: 0 | C6: 0 | D6: 0 | E6: 0 | F6: 0 | G6: 0
A7: Connecticut | B7: 0 | C7: 0 | D7: 0 | E7: 0 | F7: 0 | G7: 0
A8: Delaware | B8: 0 | C8: 0 | D8: 0 | E8: 0 | F8: 0 | G8: 0
A9: Florida | B9: 0 | C9: 0 | D9: 0 | E9: 0 | F9: 0 | G9: 0
A10: Georgia | B10: 0 | C10: 0 | D10: 0 | E10: 0 | F10: 0 | G10: 0
A11: Idaho | B11: 0 | C11: 0 | D11: 0 | E11: 0 | F11: 0 | G11: 0
A12: Illinois | B12: 0 | C12: 0 | D12: 0 | E12: 0 | F12: 0 | G12: 0
... A49: Wyoming | B49: 0 | C49: 0 | D49: 0 | E49: 0 | F49: 0 | G49: 0

Sheet BGDPbES
A1: BAU Guaranteed Dispatch (dimensionless) | B1: 2020 | C1: 2021 | D1: 2022 | E1: 2023 | F1: 2024 | G1: 2025 | H1: 2026 | I1: 2027 | J1: 2028 | K1: 2029 | L1: 2030 | M1: 2031 | N1: 2032 | O1: 2033 | P1: 2034 | Q1: 2035 | R1: 2036 | S1: 2037 | T1: 2038 | U1: 2039 | V1: 2040 | W1: 2041 | X1: 2042 | Y1: 2043 | Z1: 2044 | AA1: 2045 | AB1: 2046 | AC1: 2047 | AD1: 2048 | AE1: 2049 | AF1: 2050
A2: hard coal | B2: =SUMIFS('coal and gas factors'!B:B,'coal and gas factors'!A:A,About!$B$2) -> 0 | C2: =B2 -> 0 | D2: =C2 -> 0 | E2: =SUMIFS('CF coal 2023-2024'!F:F,'CF coal 2023-2024'!B:B,About!$B$2) -> 0.95476506 | F2: =E2 -> 0.95476506 | G2: 0 | H2: 0 | I2: 0 | J2: 0 | K2: 0 | L2: 0 | M2: 0 | N2: 0 | O2: 0 | P2: 0 | Q2: 0 | R2: 0 | S2: 0 | T2: 0 | U2: 0 | V2: 0 | W2: 0 | X2: 0 | Y2: 0 | Z2: 0 | AA2: 0 | AB2: 0 | AC2: 0 | AD2: 0 | AE2: 0 | AF2: 0
A3: natural gas steam turbine | B3: =SUMIFS('start year state specific CF'!$D:$D,'start year state specific CF'!$B:$B,About!$B$2) -> 1 | C3: =B3 -> 1 | D3: =C3 -> 1 | E3: =D3 -> 1 | F3: 0 | G3: =F3 -> 0 | H3: =G3 -> 0 | I3: =H3 -> 0 | J3: =I3 -> 0 | K3: =J3 -> 0 | L3: =K3 -> 0 | M3: =L3 -> 0 | N3: =M3 -> 0 | ... AF3: =AE3 -> 0
A4: natural gas combined cycle | B4: =SUMIFS('coal and gas factors'!C:C,'coal and gas factors'!A:A,About!$B$2) -> 0.7 | C4: =B4 -> 0.7 | D4: =C4 -> 0.7 | E4: =SUMIFS('CF nat gas 2023-2024'!B:B,'CF nat gas 2023-2024'!$A:$A,About!$B$1) -> 0 | F4: =SUMIFS('CF nat gas 2023-2024'!C:C,'CF nat gas 2023-2024'!$A:$A,About!$B$1) -> 0 | G4: =SUMIFS('CF nat gas 2023-2024'!D:D,'CF nat gas 2023-2024'!$A:$A,About!$B$1) -> 0 | H4: =SUMIFS('CF nat gas 2023-2024'!E:E,'CF nat gas 2023-2024'!$A:$A,About!$B$1) -> 0 | I4: =SUMIFS('CF nat gas 2023-2024'!F:F,'CF nat gas 2023-2024'!$A:$A,About!$B$1) -> 0 | J4: =SUMIFS('CF nat gas 2023-2024'!G:G,'CF nat gas 2023-2024'!$A:$A,About!$B$1) -> 0 | K4: 0 | L4: 0 | M4: 0 | N4: 0 | O4: 0 | P4: 0 | Q4: 0 | R4: 0 | S4: 0 | T4: 0 | U4: 0 | V4: 0 | W4: 0 | X4: 0 | Y4: 0 | Z4: 0 | AA4: 0 | AB4: 0 | AC4: 0 | AD4: 0 | AE4: 0 | AF4: 0
A5: nuclear | B5: =SUMIFS('start year state specific CF'!G:G,'start year state specific CF'!B:B,About!B2) -> 1 | C5: =B5 -> 1 | D5: 1 | E5: 1 | F5: 1 | G5: =F5 -> 1 | H5: =G5 -> 1 | I5: =H5 -> 1 | J5: =I5 -> 1 | K5: =J5 -> 1 | L5: =K5 -> 1 | M5: =L5 -> 1 | N5: =M5 -> 1 | ... AF5: =AE5 -> 1
A6: hydro | B6: =SUMIFS('start year state specific CF'!$H:$H,'start year state specific CF'!$B:$B,About!$B$2) -> 0.9 | C6: =SUMIFS('start year state specific CF'!$H:$H,'start year state specific CF'!$B:$B,About!$B$2) -> 0.9 | D6: =SUMIFS('start year state specific CF'!$H:$H,'start year state specific CF'!$B:$B,About!$B$2) -> 0.9 | E6: =SUMIFS('start year state specific CF'!$H:$H,'start year state specific CF'!$B:$B,About!$B$2) -> 0.9 | F6: =E6 -> 0.9 | G6: =F6 -> 0.9 | H6: =G6 -> 0.9 | I6: =H6 -> 0.9 | J6: =I6 -> 0.9 | K6: =J6 -> 0.9 | L6: =K6 -> 0.9 | M6: =L6 -> 0.9 | ... AF6: =AE6 -> 0.9
A7: onshore wind | B7: 1 | C7: 1 | D7: 1 | E7: 1 | F7: 0 | G7: =F7 -> 0 | H7: =G7 -> 0 | I7: =H7 -> 0 | J7: =I7 -> 0 | K7: =J7 -> 0 | L7: =K7 -> 0 | M7: =L7 -> 0 | N7: =M7 -> 0 | ... AF7: =AE7 -> 0
A8: solar PV | B8: 1 | C8: 1 | D8: 1 | E8: 1 | F8: 0 | G8: =F8 -> 0 | H8: =G8 -> 0 | I8: =H8 -> 0 | J8: =I8 -> 0 | K8: =J8 -> 0 | L8: =K8 -> 0 | M8: =L8 -> 0 | N8: =M8 -> 0 | ... AF8: =AE8 -> 0
A9: solar thermal | B9: 0 | C9: 0 | D9: 0 | E9: 0 | F9: 0 | G9: =F9 -> 0 | H9: =G9 -> 0 | I9: =H9 -> 0 | J9: =I9 -> 0 | K9: =J9 -> 0 | L9: =K9 -> 0 | M9: =L9 -> 0 | N9: =M9 -> 0 | ... AF9: =AE9 -> 0
A10: biomass | B10: 1 | C10: 1 | D10: 1 | E10: 1 | F10: 1 | G10: =F10 -> 1 | H10: =G10 -> 1 | I10: =H10 -> 1 | J10: =I10 -> 1 | K10: =J10 -> 1 | L10: =K10 -> 1 | M10: =L10 -> 1 | N10: =M10 -> 1 | ... AF10: =AE10 -> 1
A11: geothermal | B11: 1 | C11: 1 | D11: 1 | E11: 1 | F11: 1 | G11: =F11 -> 1 | H11: =G11 -> 1 | I11: =H11 -> 1 | J11: =I11 -> 1 | K11: =J11 -> 1 | L11: =K11 -> 1 | M11: =L11 -> 1 | N11: =M11 -> 1 | ... AF11: =AE11 -> 1
A12: petroleum | B12: =C12 -> 1 | C12: =SUMIFS('start year state specific CF'!I:I,'start year state specific CF'!B:B,About!$B$2) -> 1 | D12: 0.5 | E12: 0.5 | F12: 0.5 | G12: 0.5 | H12: 0.5 | I12: 0.5 | J12: 0.5 | K12: 0.5 | L12: 0.5 | M12: 0.5 | N12: 0.5 | O12: 0.5 | P12: 0.5 | Q12: 0.5 | R12: 0.5 | S12: 0.5 | T12: 0.5 | U12: 0.5 | V12: 0.5 | W12: 0.5 | X12: 0.5 | Y12: 0.5 | Z12: 0.5 | AA12: 0.5 | AB12: 0.5 | AC12: 0.5 | AD12: 0.5 | AE12: 0.5 | AF12: 0.5
A13: natural gas peaker | B13: =SUMIFS('start year state specific CF'!F:F,'start year state specific CF'!B:B,About!B2) -> 1 | C13: =B13 -> 1 | D13: 0.5 | E13: 0.5 | F13: 0.5 | G13: 0.5 | H13: 0.5 | I13: 0.5 | J13: 0.5 | K13: 0.5 | L13: 0.5 | M13: 0.5 | N13: 0.5 | O13: 0.5 | P13: 0.5 | Q13: 0.5 | R13: 0.5 | S13: 0.5 | T13: 0.5 | U13: 0.5 | V13: 0.5 | W13: 0.5 | X13: 0.5 | Y13: 0.5 | Z13: 0.5 | AA13: 0.5 | AB13: 0.5 | AC13: 0.5 | AD13: 0.5 | AE13: 0.5 | AF13: 0.5
A14: lignite | B14: 0 | C14: 0 | D14: 0 | E14: 0 | F14: 0 | G14: =F14 -> 0 | H14: =G14 -> 0 | I14: =H14 -> 0 | J14: =I14 -> 0 | K14: =J14 -> 0 | L14: =K14 -> 0 | M14: =L14 -> 0 | N14: =M14 -> 0 | ... AF14: =AE14 -> 0
A15: offshore wind | B15: 0 | C15: 0 | D15: 0 | E15: 0 | F15: 0 | G15: 0 | H15: 0 | I15: 0 | J15: 0 | K15: 0 | L15: 0 | M15: 0 | N15: 0 | O15: 0 | P15: 0 | Q15: 0 | R15: 0 | S15: 0 | T15: 0 | U15: 0 | V15: 0 | W15: 0 | X15: 0 | Y15: 0 | Z15: 0 | AA15: 0 | AB15: 0 | AC15: 0 | AD15: 0 | AE15: 0 | AF15: 0
A16: crude oil | B16: =SUMIFS('start year state specific CF'!J:J,'start year state specific CF'!B:B,About!$B$2) -> 1 | C16: =B16 -> 1 | D16: =C16 -> 1 | E16: =D16 -> 1 | F16: =E16 -> 1 | G16: =F16 -> 1 | H16: =G16 -> 1 | I16: =H16 -> 1 | J16: =I16 -> 1 | ... AF16: =AE16 -> 1
A17: heavy or residual fuel oil | B17: 0 | C17: 0 | D17: 0 | E17: 0 | F17: 0 | G17: =F17 -> 0 | H17: =G17 -> 0 | I17: =H17 -> 0 | J17: =I17 -> 0 | K17: =J17 -> 0 | L17: =K17 -> 0 | M17: =L17 -> 0 | N17: =M17 -> 0 | ... AF17: =AE17 -> 0
A18: municipal solid waste | B18: 0 | C18: 0 | D18: 0 | E18: 0 | F18: 0 | G18: =F18 -> 0 | H18: =G18 -> 0 | I18: =H18 -> 0 | J18: =I18 -> 0 | K18: =J18 -> 0 | L18: =K18 -> 0 | M18: =L18 -> 0 | N18: =M18 -> 0 | ... AF18: =AE18 -> 0
A19: hard coal w CCS | B19: 0.15 | C19: 0.15 | D19: 0.15 | E19: 0.15 | F19: 0.15 | G19: =F19 -> 0.15 | H19: =G19 -> 0.15 | I19: =H19 -> 0.15 | J19: =I19 -> 0.15 | K19: =J19 -> 0.15 | L19: =K19 -> 0.15 | M19: =L19 -> 0.15 | N19: =M19 -> 0.15 | ... AF19: =AE19 -> 0.15
A20: natural gas combined cycle w CCS | B20: 0.15 | C20: 0.15 | D20: 0.15 | E20: 0.15 | F20: 0.15 | G20: =F20 -> 0.15 | H20: =G20 -> 0.15 | I20: =H20 -> 0.15 | J20: =I20 -> 0.15 | K20: =J20 -> 0.15 | L20: =K20 -> 0.15 | M20: =L20 -> 0.15 | N20: =M20 -> 0.15 | ... AF20: =AE20 -> 0.15
A21: biomass w CCS | B21: 0.15 | C21: 0.15 | D21: 0.15 | E21: 0.15 | F21: 0.15 | G21: =F21 -> 0.15 | H21: =G21 -> 0.15 | I21: =H21 -> 0.15 | J21: =I21 -> 0.15 | K21: =J21 -> 0.15 | L21: =K21 -> 0.15 | M21: =L21 -> 0.15 | N21: =M21 -> 0.15 | ... AF21: =AE21 -> 0.15
A22: lignite w CCS | B22: 0.15 | C22: 0.15 | D22: 0.15 | E22: 0.15 | F22: 0.15 | G22: =F22 -> 0.15 | H22: =G22 -> 0.15 | I22: =H22 -> 0.15 | J22: =I22 -> 0.15 | K22: =J22 -> 0.15 | L22: =K22 -> 0.15 | M22: =L22 -> 0.15 | N22: =M22 -> 0.15 | ... AF22: =AE22 -> 0.15
A23: small modular reactor | B23: 0 | C23: 0 | D23: 0 | E23: 0 | F23: 0 | G23: =F23 -> 0 | H23: =G23 -> 0 | I23: =H23 -> 0 | J23: =I23 -> 0 | K23: =J23 -> 0 | L23: =K23 -> 0 | M23: =L23 -> 0 | N23: =M23 -> 0 | ... AF23: =AE23 -> 0
A24: hydrogen combustion turbine | B24: 1 | C24: 1 | D24: 1 | E24: 1 | F24: 1 | G24: =F24 -> 1 | H24: =G24 -> 1 | I24: =H24 -> 1 | J24: =I24 -> 1 | K24: =J24 -> 1 | L24: =K24 -> 1 | M24: =L24 -> 1 | N24: =M24 -> 1 | ... AF24: =AE24 -> 1
A25: hydrogen combined cycle | B25: 1 | C25: 1 | D25: 1 | E25: 1 | F25: 1 | G25: =F25 -> 1 | H25: =G25 -> 1 | I25: =H25 -> 1 | J25: =I25 -> 1 | K25: =J25 -> 1 | L25: =K25 -> 1 | M25: =L25 -> 1 | N25: =M25 -> 1 | ... AF25: =AE25 -> 1
